Workbook

Sheet Prévisions Mois N
B1: ESTIMATION | P1: VARIATION R 16 sur B16 & R15
B2: BASE | E2: CA GENERE | P2: R16 | R2: Variation Réel 16 / B16 | U2: Variation Réel 16 / Réel 15 | X2: Commentaires
B3: LOYER | C3: Plog & Divers | D3: Total BASE | E3: IMAR | F3: HINT | G3: IAER | H3: EAER | I3: AERIEN | J3: EXPORT | K3: SIRT | L3: Afritramp | M3: Meet & Greet | N3: CA GENERE Autres département | O3: CA TOTAL GENERE PAR CLIENT | P3: Sources revenus | Q3: REEL BASE 2016 | R3: Budget 2016 | S3: VAR (FCFA) | T3: Var (%) | U3: Réel BASE 2015 | V3: VAR (FCFA) | W3: Var (%)
A4: Afritramp C/O SAGA | C4: =D4-B4 | I4: =H4+G4 | N4: =J4+I4+F4+E4+L4+M4+K4 | O4: =N4+D4 | P4: Afritramp C/O SAGA | Q4: =D4 | R4: 0 | S4: =Q4-R4 | T4: =Q4/R4-1 | V4: =Q4-U4 | W4: =(Q4/U4-1)
A5: Antrak Ghana (Tullow Oil) | C5: =D5-B5 | I5: =H5+G5 | N5: =J5+I5+F5+E5+L5+M5+K5 | O5: =N5+D5 | P5: Antrak Ghana (Tullow Oil) | Q5: =D5 | R5: 0 | S5: =Q5-R5 | T5: =Q5/R5-1 | V5: =Q5-U5 | W5: =(Q5/U5-1)
A6: Anadarko | C6: =D6-B6 | I6: =H6+G6 | N6: =J6+I6+F6+E6+L6+M6+K6 | O6: =N6+D6 | P6: Anadarko | Q6: =D6 | R6: 10416667 | S6: =Q6-R6 | T6: =Q6/R6-1 | U6: =116080+17732160 | V6: =Q6-U6 | W6: =(Q6/U6-1)
A7: Baker Hugues | C7: =D7-B7 | I7: =H7+G7 | N7: =J7+I7+F7+E7+L7+M7+K7 | O7: =N7+D7 | P7: Baker Hugues | Q7: =D7 | R7: 13833333 | S7: =Q7-R7 | T7: =Q7/R7-1 | U7: 20563873 | V7: =Q7-U7 | W7: =(Q7/U7-1)
A8: BOURBON | C8: =D8-B8 | I8: =H8+G8 | N8: =J8+I8+F8+E8+L8+M8+K8 | O8: =N8+D8 | P8: BOURBON | Q8: =D8 | R8: 0 | S8: =Q8-R8 | T8: =Q8/R8-1 | V8: =Q8-U8 | W8: =(Q8/U8-1)
A9: CGG Veritas | C9: =D9-B9 | I9: =H9+G9 | N9: =J9+I9+F9+E9+L9+M9+K9 | O9: =N9+D9 | P9: CGG Veritas | Q9: =D9 | R9: 0 | S9: =Q9-R9 | T9: =Q9/R9-1 | V9: =Q9-U9 | W9: =(Q9/U9-1)
A10: CIAM | C10: =D10-B10 | I10: =H10+G10 | N10: =J10+I10+F10+E10+L10+M10+K10 | O10: =N10+D10 | P10: CIAM | Q10: =D10 | R10: 2083333.3 | S10: =Q10-R10 | T10: =Q10/R10-1 | U10: 715000 | V10: =Q10-U10 | W10: =(Q10/U10-1)
A11: CNR | C11: =D11-B11 | I11: =H11+G11 | N11: =J11+I11+F11+E11+L11+M11+K11 | O11: =N11+D11 | P11: CNR | Q11: =D11 | R11: 81666667 | S11: =Q11-R11 | T11: =Q11/R11-1 | U11: 91764418 | V11: =Q11-U11 | W11: =(Q11/U11-1)
A12: DIVERS/Various customer | C12: =D12-B12 | I12: =H12+G12 | N12: =J12+I12+F12+E12+L12+M12+K12 | O12: =N12+D12 | P12: DIVERS/Various customer | Q12: =D12 | R12: 39583333 | S12: =Q12-R12 | T12: =Q12/R12-1 | U12: -83126 | V12: =Q12-U12 | W12: =(Q12/U12-1)
A13: dolphin drilling | C13: =D13-B13 | I13: =H13+G13 | N13: =J13+I13+F13+E13+L13+M13+K13 | O13: =N13+D13 | P13: dolphin drilling | Q13: =D13 | R13: 0 | S13: =Q13-R13 | T13: =Q13/R13-1 | V13: =Q13-U13 | W13: =(Q13/U13-1)
A14: ExxonMobil | C14: =D14-B14 | I14: =H14+G14 | N14: =J14+I14+F14+E14+L14+M14+K14 | O14: =N14+D14 | P14: ExxonMobil | Q14: =D14 | R14: 0 | S14: =Q14-R14 | T14: =Q14/R14-1 | V14: =Q14-U14 | W14: =(Q14/U14-1)
A15: EXPRO GROUP NORTH SEA / S-Traitant | C15: =D15-B15 | I15: =H15+G15 | N15: =J15+I15+F15+E15+L15+M15+K15 | O15: =N15+D15 | P15: EXPRO GROUP NORTH SEA / S-Traitant | Q15: =D15 | R15: 8250000 | S15: =Q15-R15 | T15: =Q15/R15-1 | U15: 5122000 | V15: =Q15-U15 | W15: =(Q15/U15-1)
A16: FUGRO | C16: =D16-B16 | I16: =H16+G16 | N16: =J16+I16+F16+E16+L16+M16+K16 | O16: =N16+D16 | P16: FMC / Assistance | Q16: =D16 | R16: 0 | S16: =Q16-R16 | T16: =Q16/R16-1 | V16: =Q16-U16 | W16: =(Q16/U16-1)
A17: FOXTROT | C17: =D17-B17 | I17: =H17+G17 | N17: =J17+I17+F17+E17+L17+M17+K17 | O17: =N17+D17 | P17: FOXTROT | Q17: =D17 | R17: 65416667 | S17: =Q17-R17 | T17: =Q17/R17-1 | U17: 106573674 | V17: =Q17-U17 | W17: =(Q17/U17-1)
A18: Franks International | C18: =D18-B18 | I18: =H18+G18 | N18: =J18+I18+F18+E18+L18+M18+K18 | O18: =N18+D18 | P18: FUGRO / Assistance | Q18: =D18 | R18: 0 | S18: =Q18-R18 | T18: =Q18/R18-1 | V18: =Q18-U18 | W18: =(Q18/U18-1)
A19: GLOBAL ENERGY | C19: =D19-B19 | I19: =H19+G19 | N19: =J19+I19+F19+E19+L19+M19+K19 | O19: =N19+D19 | P19: GLOBAL ENERGY | Q19: =D19 | R19: 4166666.7 | S19: =Q19-R19 | T19: =Q19/R19-1 | U19: 4118387 | V19: =Q19-U19 | W19: =(Q19/U19-1)
A20: GULF OFFSHORE(NS) LTD | C20: =D20-B20 | I20: =H20+G20 | N20: =J20+I20+F20+E20+L20+M20+K20 | O20: =N20+D20 | P20: GULF OFFSHORE(NS) LTD | Q20: =D20 | R20: 0 | S20: =Q20-R20 | T20: =Q20/R20-1 | V20: =Q20-U20 | W20: =(Q20/U20-1)
A21: HALLIBURTON | C21: =D21-B21 | I21: =H21+G21 | N21: =J21+I21+F21+E21+L21+M21+K21 | O21: =N21+D21 | P21: HALLIBURTON | Q21: =D21 | R21: 33333333 | S21: =Q21-R21 | T21: =Q21/R21-1 | U21: 48316159 | V21: =Q21-U21 | W21: =(Q21/U21-1)
A22: SAGA ITALIE | C22: =D22-B22 | I22: =H22+G22 | N22: =J22+I22+F22+E22+L22+M22+K22 | O22: =N22+D22 | P22: INTERSHIP | Q22: =D22 | R22: 0 | S22: =Q22-R22 | T22: =Q22/R22-1 | U22: -327500 | V22: =Q22-U22 | W22: =(Q22/U22-1)
A23: KCA Deutag | C23: =D23-B23 | I23: =H23+G23 | N23: =J23+I23+F23+E23+L23+M23+K23 | O23: =N23+D23 | P23: KCA Deutag | Q23: =D23 | R23: 0 | S23: =Q23-R23 | T23: =Q23/R23-1 | V23: =Q23-U23 | W23: =(Q23/U23-1)
A24: LUKOIL | C24: =D24-B24 | I24: =H24+G24 | N24: =J24+I24+F24+E24+L24+M24+K24 | O24: =N24+D24 | P24: LUKOIL | Q24: =D24 | R24: 0 | S24: =Q24-R24 | T24: =Q24/R24-1 | U24: 86200 | V24: =Q24-U24 | W24: =(Q24/U24-1)
A25: MI | I25: =H25+G25 | N25: =J25+I25+F25+E25+L25+M25+K25 | O25: =N25+D25 | P25: MI | Q25: =D25 | R25: 16666667 | S25: =Q25-R25 | T25: =Q25/R25-1 | U25: 25310375 | V25: =Q25-U25 | W25: =(Q25/U25-1)
A26: National Oilwell Varcouk | C26: =D26-B26 | I26: =H26+G26 | N26: =J26+I26+F26+E26+L26+M26+K26 | O26: =N26+D26 | P26: National Oilwell Varcouk | Q26: =D26 | R26: 0 | S26: =Q26-R26 | T26: =Q26/R26-1 | V26: =Q26-U26 | W26: =(Q26/U26-1)
A27: NOPCI - MODEC | C27: =D27-B27 | I27: =H27+G27 | N27: =J27+I27+F27+E27+L27+M27+K27 | O27: =N27+D27 | P27: NOPCI - MODEC | Q27: =D27 | R27: 833333.33 | S27: =Q27-R27 | T27: =Q27/R27-1 | U27: 80235 | V27: =Q27-U27 | W27: =(Q27/U27-1)
A28: MICOPERI | C28: =D28-B28 | I28: =H28+G28 | N28: =J28+I28+F28+E28+L28+M28+K28 | O28: =N28+D28 | P28: MICOPERI | Q28: =D28 | R28: 0 | S28: =Q28-R28 | T28: =Q28/R28-1 | U28: 10890950 | V28: =Q28-U28 | W28: =(Q28/U28-1)
A29: PENTAGON FREIGHT | C29: =D29-B29 | I29: =H29+G29 | N29: =J29+I29+F29+E29+L29+M29+K29 | O29: =N29+D29 | P29: PENTAGON FREIGHT | Q29: =D29 | R29: 0 | S29: =Q29-R29 | T29: =Q29/R29-1 | V29: =Q29-U29 | W29: =(Q29/U29-1)
A30: Prosafe | C30: =D30-B30 | I30: =H30+G30 | N30: =J30+I30+F30+E30+L30+M30+K30 | O30: =N30+D30 | P30: Prosafe | Q30: =D30 | R30: 41666.667 | S30: =Q30-R30 | T30: =Q30/R30-1 | U30: 223850 | V30: =Q30-U30 | W30: =(Q30/U30-1)
A31: Saphire Driller (Vantage) | C31: =D31-B31 | I31: =H31+G31 | N31: =J31+I31+F31+E31+L31+M31+K31 | O31: =N31+D31 | P31: Saphire Driller (Vantage) | Q31: =D31 | R31: 0 | S31: =Q31-R31 | T31: =Q31/R31-1 | V31: =Q31-U31 | W31: =(Q31/U31-1)
A32: BOLLORE NORWAY (PROSAFE) | C32: =D32-B32 | I32: =H32+G32 | N32: =J32+I32+F32+E32+L32+M32+K32 | O32: =N32+D32 | P32: SDV BELGIUM | Q32: =D32 | R32: 0 | S32: =Q32-R32 | T32: =Q32/R32-1 | V32: =Q32-U32 | W32: =(Q32/U32-1)
A33: SDV GHANA | C33: =D33-B33 | I33: =H33+G33 | N33: =J33+I33+F33+E33+L33+M33+K33 | O33: =N33+D33 | P33: SDV GHANA | Q33: =D33 | R33: 0 | S33: =Q33-R33 | T33: =Q33/R33-1 | V33: =Q33-U33 | W33: =(Q33/U33-1)
A34: SDV Usa | C34: =D34-B34 | I34: =H34+G34 | N34: =J34+I34+F34+E34+L34+M34+K34 | O34: =N34+D34 | P34: SDV Usa | Q34: =D34 | R34: 0 | S34: =Q34-R34 | T34: =Q34/R34-1 | V34: =Q34-U34 | W34: =(Q34/U34-1)
A35: BOLLORE SINGAPORE | C35: =D35-B35 | I35: =H35+G35 | N35: =J35+I35+F35+E35+L35+M35+K35 | O35: =N35+D35 | P35: SDV Logistic Singapore (Prosafe) | Q35: =D35 | R35: 166666.67 | S35: =Q35-R35 | T35: =Q35/R35-1 | U35: 297000 | V35: =Q35-U35 | W35: =(Q35/U35-1)
A36: BOLLORE DIVERS | C36: =D36-B36 | I36: =H36+G36 | N36: =J36+I36+F36+E36+L36+M36+K36 | O36: =N36+D36 | P36: SDV Pau | Q36: =D36 | R36: 0 | S36: =Q36-R36 | T36: =Q36/R36-1 | V36: =Q36-U36 | W36: =(Q36/U36-1)
A37: SUBSEA7 | C37: =D37-B37 | I37: =H37+G37 | N37: =J37+I37+F37+E37+L37+M37+K37 | O37: =N37+D37 | P37: SUBSEA7 | Q37: =D37 | R37: 0 | S37: =Q37-R37 | T37: =Q37/R37-1 | U37: 74500 | V37: =Q37-U37 | W37: =(Q37/U37-1)
A38: SCHLUMBERGER | C38: =D38-B38 | I38: =H38+G38 | N38: =J38+I38+F38+E38+L38+M38+K38 | O38: =N38+D38 | P38: SCHLUMBERGER | Q38: =D38 | R38: 44166667 | S38: =Q38-R38 | T38: =Q38/R38-1 | U38: 72038469 | V38: =Q38-U38 | W38: =(Q38/U38-1)
A39: Sapura Kencana Drilling | C39: =D39-B39 | I39: =H39+G39 | N39: =J39+I39+F39+E39+L39+M39+K39 | O39: =N39+D39 | P39: Sapura Kencana Drilling | Q39: =D39 | R39: 2083333.3 | S39: =Q39-R39 | T39: =Q39/R39-1 | U39: =602906+25000 | V39: =Q39-U39 | W39: =(Q39/U39-1)
A40: SIR P/C Subtec | C40: =D40-B40 | I40: =H40+G40 | N40: =J40+I40+F40+E40+L40+M40+K40 | O40: =N40+D40 | P40: SIR P/C Subtec | Q40: =D40 | R40: 166666.67 | S40: =Q40-R40 | T40: =Q40/R40-1 | U40: 1152605 | V40: =Q40-U40 | W40: =(Q40/U40-1)
...

Sheet Occupation (2)
B3: Base 1 (Oil & Gas Vridi) | C3: Oil & Gas ALCI
B4: Base 2 (Extension SEPBA) | C4: Occupied spaces | S4: Finance | Z4: Comments on last tariffs update
B5: SOUS BAIL | C5: Warehousing | F5: Yard Clay | I5: Yard Concrete | L5: Offices | O5: Shed
B6: Clients | C6: Superficie (sqm) | D6: Price per Sqm | E6: Amount | F6: Superficie (sqm) | G6: Price per Sqm | H6: Amount | I6: Superficie (sqm) | J6: Price per Sqm | K6: Amount | L6: Superficie (sqm) | M6: Price per Sqm | N6: Amount | O6: Superficie (sqm) | P6: Price per Sqm | Q6: Amount | R6: Reel2011 | S6: Reel 2011 € | T6: 2012 Forecast | U6: 2012 Forecast € | V6: Monthly Revenue | W6: 2013 Budget € | X6: Actually Invoiced | Y6: Difference
B7: Afritramp | E7: =D7*C7 | H7: =G7*F7 | K7: =J7*I7 | N7: =M7*L7 | Q7: =P7*O7 | R7: 288 | S7: =R7*1000/655.957 | T7: 0 | U7: =T7*1000/655.957 | V7: =Q7+N7+K7+H7+E7 | W7: =V7*1000/655.957 | Y7: =X7-V7
B8: ANADARKO | D8: 5000 | E8: =D8*C8 | F8: 5000 | G8: 1750 | H8: =G8*F8 | K8: =J8*I8 | N8: =M8*L8 | Q8: =P8*O8 | R8: =540+10776+6662 | S8: =R8*1000/655.957 | T8: 46700 | U8: =T8*1000/655.957 | V8: =Q8+N8+K8+H8+E8 | W8: =V8*1000/655.957 | X8: 8750000 | Y8: =X8-V8
B9: ANTRAK GHANA (Tullow Oil) | E9: =D9*C9 | H9: =G9*F9 | K9: =J9*I9 | N9: =M9*L9 | Q9: =P9*O9 | R9: 5851 | S9: =R9*1000/655.957 | T9: 9400 | U9: =T9*1000/655.957 | V9: =Q9+N9+K9+H9+E9 | W9: =V9*1000/655.957 | Y9: =X9-V9
B10: Baker Hugues | C10: 1166 | D10: 572 | E10: =D10*C10 | G10: 750 | H10: =G10*F10 | I10: 1786 | J10: 1150 | K10: =J10*I10 | L10: 92 | M10: 10000 | N10: =M10*L10 | P10: 1150 | Q10: =P10*O10 | R10: 57345 | S10: =R10*1000/655.957 | T10: 125500 | U10: =T10*1000/655.957 | V10: =Q10+N10+K10+H10+E10 | W10: =V10*1000/655.957 | X10: 5611000 | Y10: =X10-V10
B11: BOURBON | E11: =D11*C11 | H11: =G11*F11 | K11: =J11*I11 | N11: =M11*L11 | Q11: =P11*O11 | R11: 180 | S11: =R11*1000/655.957 | T11: 0 | U11: =T11*1000/655.957 | V11: =Q11+N11+K11+H11+E11 | W11: =V11*1000/655.957 | Y11: =X11-V11
B12: CGGVERITAS | E12: =D12*C12 | H12: =G12*F12 | K12: =J12*I12 | N12: =M12*L12 | Q12: =P12*O12 | S12: =R12*1000/655.957 | T12: 23500 | U12: =T12*1000/655.957 | V12: =Q12+N12+K12+H12+E12 | W12: =V12*1000/655.957 | Y12: =X12-V12
B13: CNR | C13: 2800 | D13: 2500 | E13: =D13*C13 | F13: 20000 | G13: 1250 | H13: =G13*F13 | K13: =J13*I13 | N13: =M13*L13 | Q13: =P13*O13 | R13: 95699 | S13: =R13*1000/655.957 | T13: 248000 | U13: =T13*1000/655.957 | V13: =Q13+N13+K13+H13+E13 | W13: =V13*1000/655.957 | X13: 29250000 | Y13: =X13-V13
B14: DIVERS/various custumers | E14: =D14*C14 | H14: =G14*F14 | K14: =J14*I14 | N14: =M14*L14 | Q14: =P14*O14 | R14: =1082+3497+19330 | S14: =R14*1000/655.957 | T14: 28500 | U14: =T14*1000/655.957 | V14: =Q14+N14+K14+H14+E14 | W14: =V14*1000/655.957 | Y14: =X14-V14
B15: DOLPHIN DRILLING | E15: =D15*C15 | H15: =G15*F15 | K15: =J15*I15 | N15: =M15*L15 | Q15: =P15*O15 | S15: =R15*1000/655.957 | T15: 0 | U15: =T15*1000/655.957 | V15: =Q15+N15+K15+H15+E15 | W15: =V15*1000/655.957 | Y15: =X15-V15
B16: EDISON INTERNATIONAL | E16: =D16*C16 | H16: =G16*F16 | K16: =J16*I16 | N16: =M16*L16 | Q16: =P16*O16 | R16: 71 | S16: =R16*1000/655.957 | T16: 0 | U16: =T16*1000/655.957 | V16: =Q16+N16+K16+H16+E16 | W16: =V16*1000/655.957 | Y16: =X16-V16
B17: EMAR | E17: =D17*C17 | H17: =G17*F17 | K17: =J17*I17 | N17: =M17*L17 | Q17: =P17*O17 | S17: =R17*1000/655.957 | U17: =T17*1000/655.957 | V17: =Q17+N17+K17+H17+E17 | W17: =V17*1000/655.957 | Y17: =X17-V17
B18: EXPRO GROUP NORTH SEA / S-Traitant | C18: 217 | E18: =D18*C18 | F18: 562 | H18: =G18*F18 | I18: 2114 | K18: =J18*I18 | L18: 216 | N18: =M18*L18 | O18: 351 | Q18: =P18*O18 | R18: 76767 | S18: =R18*1000/655.957 | T18: 73000 | U18: =T18*1000/655.957 | V18: =Q18+N18+K18+H18+E18 | W18: =V18*1000/655.957 | X18: 4784000 | Y18: =X18-V18
B19: FOXTROT | C19: 4500 | D19: 2500 | E19: =D19*C19 | F19: 1290 | G19: 550 | H19: =G19*F19 | I19: 3262 | J19: 1000 | K19: =J19*I19 | N19: =M19*L19 | Q19: =P19*O19 | R19: 118138 | S19: =R19*1000/655.957 | T19: 394740 | U19: =T19*1000/655.957 | V19: =Q19+N19+K19+H19+E19 | W19: =V19*1000/655.957 | X19: 6609000 | Y19: =X19-V19
B20: GLOBAL ENERGY | C20: 218.5 | D20: 2500 | E20: =D20*C20 | F20: 128 | G20: 1450 | H20: =G20*F20 | I20: 1037 | J20: 1450 | K20: =J20*I20 | L20: 25 | M20: 11500 | N20: =M20*L20 | O20: 103 | Q20: =P20*O20 | R20: 33944 | S20: =R20*1000/655.957 | T20: 77540 | U20: =T20*1000/655.957 | V20: =Q20+N20+K20+H20+E20 | W20: =V20*1000/655.957 | X20: 1890000 | Y20: =X20-V20
B21: Global forwarding DHL | E21: =D21*C21 | H21: =G21*F21 | K21: =J21*I21 | N21: =M21*L21 | Q21: =P21*O21 | R21: 835 | S21: =R21*1000/655.957 | T21: 0 | U21: =T21*1000/655.957 | V21: =Q21+N21+K21+H21+E21 | W21: =V21*1000/655.957 | Y21: =X21-V21
B22: Gulf OFFSHORE | E22: =D22*C22 | H22: =G22*F22 | K22: =J22*I22 | N22: =M22*L22 | Q22: =P22*O22 | S22: =R22*1000/655.957 | T22: 4600 | U22: =T22*1000/655.957 | V22: =Q22+N22+K22+H22+E22 | W22: =V22*1000/655.957 | Y22: =X22-V22
B23: HALLIBURTON | D23: 2500 | E23: =D23*C23 | H23: =G23*F23 | J23: 1570 | K23: =J23*I23 | L23: 94 | M23: 13000 | N23: =M23*L23 | Q23: =P23*O23 | R23: 100629 | S23: =R23*1000/655.957 | T23: 287780 | U23: =T23*1000/655.957 | V23: =Q23+N23+K23+H23+E23 | W23: =V23*1000/655.957 | X23: 7142000 | Y23: =X23-V23
B24: HINTERLAND | E24: =D24*C24 | H24: =G24*F24 | K24: =J24*I24 | N24: =M24*L24 | Q24: =P24*O24 | S24: =R24*1000/655.957 | U24: =T24*1000/655.957 | V24: =Q24+N24+K24+H24+E24 | W24: =V24*1000/655.957 | Y24: =X24-V24
B25: Intership | E25: =D25*C25 | H25: =G25*F25 | K25: =J25*I25 | N25: =M25*L25 | Q25: =P25*O25 | R25: 170 | S25: =R25*1000/655.957 | U25: =T25*1000/655.957 | V25: =Q25+N25+K25+H25+E25 | W25: =V25*1000/655.957 | Y25: =X25-V25
B26: KCAD | E26: =D26*C26 | H26: =G26*F26 | K26: =J26*I26 | N26: =M26*L26 | Q26: =P26*O26 | S26: =R26*1000/655.957 | T26: 43500 | U26: =T26*1000/655.957 | V26: =Q26+N26+K26+H26+E26 | W26: =V26*1000/655.957 | Y26: =X26-V26
B27: LGL | E27: =D27*C27 | H27: =G27*F27 | K27: =J27*I27 | N27: =M27*L27 | Q27: =P27*O27 | R27: 3733 | S27: =R27*1000/655.957 | U27: =T27*1000/655.957 | V27: =Q27+N27+K27+H27+E27 | W27: =V27*1000/655.957 | Y27: =X27-V27
B28: Lukoil | E28: =D28*C28 | H28: =G28*F28 | K28: =J28*I28 | N28: =M28*L28 | Q28: =P28*O28 | S28: =R28*1000/655.957 | T28: 7170 | U28: =T28*1000/655.957 | V28: =Q28+N28+K28+H28+E28 | W28: =V28*1000/655.957 | Y28: =X28-V28
B29: MICOPERI | E29: =D29*C29 | H29: =G29*F29 | K29: =J29*I29 | N29: =M29*L29 | Q29: =P29*O29 | R29: 73644 | S29: =R29*1000/655.957 | T29: 102000 | U29: =T29*1000/655.957 | V29: =Q29+N29+K29+H29+E29 | W29: =V29*1000/655.957 | X29: 12084000 | Y29: =X29-V29
B30: NOPCI - MODEC | E30: =D30*C30 | H30: =G30*F30 | K30: =J30*I30 | L30: 340 | M30: 5374 | N30: =M30*L30 | Q30: =P30*O30 | R30: 28646 | S30: =R30*1000/655.957 | T30: 22300 | U30: =T30*1000/655.957 | V30: =Q30+N30+K30+H30+E30 | W30: =V30*1000/655.957 | X30: =1368000+459096 | Y30: =X30-V30
B31: NOV | E31: =D31*C31 | H31: =G31*F31 | K31: =J31*I31 | N31: =M31*L31 | Q31: =P31*O31 | S31: =R31*1000/655.957 | T31: 1000 | U31: =T31*1000/655.957 | V31: =Q31+N31+K31+H31+E31 | W31: =V31*1000/655.957 | Y31: =X31-V31
B32: Ocean Rig | E32: =D32*C32 | H32: =G32*F32 | K32: =J32*I32 | N32: =M32*L32 | Q32: =P32*O32 | S32: =R32*1000/655.957 | T32: 10200 | U32: =T32*1000/655.957 | V32: =Q32+N32+K32+H32+E32 | W32: =V32*1000/655.957 | Y32: =X32-V32
B33: Rialto | E33: =D33*C33 | H33: =G33*F33 | K33: =J33*I33 | N33: =M33*L33 | Q33: =P33*O33 | S33: =R33*1000/655.957 | U33: =T33*1000/655.957 | V33: =Q33+N33+K33+H33+E33 | W33: =V33*1000/655.957 | Y33: =X33-V33
B34: SAPPHIRE DRILLER COMPANY | E34: =D34*C34 | H34: =G34*F34 | K34: =J34*I34 | N34: =M34*L34 | Q34: =P34*O34 | R34: 3954 | S34: =R34*1000/655.957 | T34: 75000 | U34: =T34*1000/655.957 | V34: =Q34+N34+K34+H34+E34 | W34: =V34*1000/655.957 | Y34: =X34-V34
B35: SAS | E35: =D35*C35 | H35: =G35*F35 | K35: =J35*I35 | N35: =M35*L35 | Q35: =P35*O35 | R35: 250 | S35: =R35*1000/655.957 | U35: =T35*1000/655.957 | V35: =Q35+N35+K35+H35+E35 | W35: =V35*1000/655.957 | Y35: =X35-V35
B36: Schlumberger (sous bail) | C36: 728 | D36: 3500 | E36: =D36*C36 | H36: =G36*F36 | I36: 830 | J36: 2000 | K36: =J36*I36 | V36: =Q36+N36+K36+H36+E36 | X36: 4208000 | Y36: =X36-V36
B37: Schlumberger | C37: 4000 | D37: 3000 | E37: =D37*C37 | F37: 392 | G37: 8000 | H37: =G37*F37 | I37: 2500 | J37: 1200 | K37: =J37*I37 | N37: =M37*L37 | Q37: =P37*O37 | R37: 6417 | S37: =R37*1000/655.957 | T37: 116400 | U37: =T37*1000/655.957 | V37: =Q37+N37+K37+H37+E37 | W37: =V37*1000/655.957 | X37: =15000000+3136000 | Y37: =X37-V37
B38: SDV Logisitc Singapore (Prosafe) | E38: =D38*C38 | H38: =G38*F38 | K38: =J38*I38 | N38: =M38*L38 | Q38: =P38*O38 | R38: 851 | S38: =R38*1000/655.957 | T38: 21000 | U38: =T38*1000/655.957 | V38: =Q38+N38+K38+H38+E38 | W38: =V38*1000/655.957 | Y38: =X38-V38
B39: SDV USA | E39: =D39*C39 | H39: =G39*F39 | K39: =J39*I39 | N39: =M39*L39 | Q39: =P39*O39 | R39: 65 | S39: =R39*1000/655.957 | T39: 8000 | U39: =T39*1000/655.957 | V39: =Q39+N39+K39+H39+E39 | W39: =V39*1000/655.957 | Y39: =X39-V39
B40: SIMEX | E40: =D40*C40 | H40: =G40*F40 | J40: 1000 | K40: =J40*I40 | L40: 26 | M40: 1815 | N40: =M40*L40 | Q40: =P40*O40 | S40: =R40*1000/655.957 | T40: 1430 | U40: =T40*1000/655.957 | V40: =Q40+N40+K40+H40+E40 | W40: =V40*1000/655.957 | X40: 182200 | Y40: =X40-V40 | Z40: Inclus TVA + éléctricité
B41: SIRT | E41: =D41*C41 | H41: =G41*F41 | K41: =J41*I41 | N41: =M41*L41 | Q41: =P41*O41 | S41: =R41*1000/655.957 | U41: =T41*1000/655.957 | V41: =Q41+N41+K41+H41+E41 | W41: =V41*1000/655.957 | Y41: =X41-V41
B42: SMB | E42: =D42*C42 | H42: =G42*F42 | K42: =J42*I42 | N42: =M42*L42 | Q42: =P42*O42 | R42: 15120 | S42: =R42*1000/655.957 | T42: 23000 | U42: =T42*1000/655.957 | V42: =Q42+N42+K42+H42+E42 | W42: =V42*1000/655.957 | Y42: =X42-V42
...

Sheet Gestion base logistique
A1: KCFA
B2: Janvier | E2: Février | H2: Mars | K2: Avril | N2: Mai | Q2: Juin | T2: Juillet | W2: Août | Z2: Septembre | AC2: Octobre | AF2: Novembre | AI2: Décembre | AL2: Fin décembre
B3: Prévu | C3: Réel | D3: Variation | E3: Prévu | F3: Réel | G3: Variation | H3: Prévu | I3: Réel | J3: Variation | K3: Prévu | L3: Réel | M3: Variation | N3: Prévu | O3: Réel | P3: Variation | Q3: Prévu | R3: Réel | S3: Variation | T3: Prévu | U3: Réel | V3: Variation | W3: Prévu | X3: Réel | Y3: Variation | Z3: Prévu | AA3: Réel | AB3: Variation | AC3: Prévu | AD3: Réel | AE3: Variation | AF3: Prévu | AG3: Réel | AH3: Variation | AI3: Prévu | AJ3: Réel | AK3: Variation | AL3: Prévu | AM3: Réel | AN3: Variation
A4: CAP NET (+) | B4: 383001.26 | E4: 423324.1 | H4: 370041.77 | K4: 410287.6 | N4: 366429.89 | Q4: 347047.59 | T4: 412800.49 | W4: 368163.67 | Z4: 344917.99 | AC4: 357441.1 | AF4: 474908.08 | AI4: 421438.13 | AL4: 4679801.7
A5: Salaires & charges de personnel (-) | B5: -30458.855 | E5: -30458.855 | H5: -30458.855 | K5: -30458.855 | N5: -30458.855 | Q5: -30458.855 | T5: -30458.855 | W5: -30458.855 | Z5: -30458.855 | AC5: -30458.855 | AF5: -30458.855 | AI5: -30459.006 | AL5: -365506.41
A6: Frais de personnel temporaire (-) | B6: -28759.291 | E6: -28759.291 | H6: -28759.291 | K6: -28759.291 | N6: -28759.291 | Q6: -28759.291 | T6: -28759.291 | W6: -28759.291 | Z6: -28759.291 | AC6: -28759.291 | AF6: -28759.291 | AI6: -28759.431 | AL6: -345111.63
A7: Dotations nettes aux amortissements (+/-) | B7: -18286.979 | E7: -18286.979 | H7: -18286.979 | K7: -18286.979 | N7: -18286.979 | Q7: -18286.979 | T7: -18286.979 | W7: -18286.979 | Z7: -18286.979 | AC7: -18286.979 | AF7: -18286.979 | AI7: -18287.035 | AL7: -219443.81
A8: Frais postaux et télécommunications (-) | B8: -1807.8701 | E8: -1807.8701 | H8: -1807.8701 | K8: -1807.8701 | N8: -1807.8701 | Q8: -1807.8701 | T8: -1807.8701 | W8: -1807.8701 | Z8: -1807.8701 | AC8: -1807.8701 | AF8: -1807.8701 | AI8: -1807.8741 | AL8: -21694.445
A9: Autres locations (-) | B9: -110987.58 | E9: -124861.03 | H9: -110987.58 | K9: -138734.47 | N9: -110987.58 | Q9: -97114.132 | T9: -124861.03 | W9: -110987.58 | Z9: -97114.132 | AC9: -97114.132 | AF9: -152607.92 | AI9: -110987.58 | AL9: -1387344.7
A10: Entretien et réparations (-) | B10: -14115.066 | E10: -15616.301 | H10: -12441.274 | K10: -18756.817 | N10: -13511.12 | Q10: -10853.761 | T10: -15219.423 | W10: -12855.408 | Z10: -11026.317 | AC10: -11492.217 | AF10: -21138.087 | AI10: -15530.023 | AL10: -172555.81
A11: Frais de consommables (-) | B11: -22137.591 | E11: -24492.078 | H11: -19512.474 | K11: -29417.557 | N11: -21190.384 | Q11: -17022.671 | T11: -23869.628 | W11: -20161.987 | Z11: -17293.302 | AC11: -18024.005 | AF11: -33152.261 | AI11: -24356.763 | AL11: -270630.7
A12: Frais de sous-traitance (-) | B12: -20244.808 | E12: -20244.808 | H12: -20244.808 | K12: -20244.808 | N12: -20244.808 | Q12: -20244.808 | T12: -20244.808 | W12: -20244.808 | Z12: -20244.808 | AC12: -20244.808 | AF12: -20244.808 | AI12: -20244.904 | AL12: -242937.79
A13: Assurances (primes, indemnités) (-) | B13: -3040.8863 | E13: -3040.8863 | H13: -3040.8863 | K13: -3040.8863 | N13: -3040.8863 | Q13: -3040.8863 | T13: -3040.8863 | W13: -3040.8863 | Z13: -3040.8863 | AC13: -3040.8863 | AF13: -3040.8863 | AI13: -3040.9063 | AL13: -36490.656
A14: Impôts et taxes (-) | B14: -19732.727 | E14: -19732.727 | H14: -19732.727 | K14: -19732.727 | N14: -19732.727 | Q14: -19732.727 | T14: -11565.518 | W14: -11565.518 | Z14: -11565.518 | AC14: -11565.518 | AF14: -11565.518 | AI14: -11527.968 | AL14: -187751.92
A15: Frais de région (-) | B15: 0 | E15: 0 | H15: 0 | K15: 0 | N15: 0 | Q15: 0 | T15: 0 | W15: 0 | Z15: 0 | AC15: 0 | AF15: 0 | AI15: 0 | AL15: 0
... A34: Résultat opérationnel avant allocation (+/-) | B34: 105498.3 | E34: 128091.98 | H34: 96837.722 | K34: 93116.035 | N34: 90478.091 | Q34: 91794.314 | T34: 126754.9 | W34: 102063.18 | Z34: 97388.731 | AC34: 108715.24 | AF34: 145914.31 | AI34: 148505.3 | AL34: 1335158.1
A35: Part du CA Net annuel | B35: =B4/$AL$4 | E35: =E4/$AL$4 | H35: =H4/$AL$4 | K35: =K4/$AL$4 | N35: =N4/$AL$4 | Q35: =Q4/$AL$4 | T35: =T4/$AL$4 | W35: =W4/$AL$4 | Z35: =Z4/$AL$4 | AC35: =AC4/$AL$4 | AF35: =AF4/$AL$4 | AI35: =AI4/$AL$4

Sheet Récap Global
B1: CAP Généré par Département sur Clients O&G (Après rétrocessions)
C3: Base O&G | D3: Import Maritime | E3: Hinterland | F3: Aérien | G3: Export Maritime | H3: Afritramp | I3: Meet & Greet | J3: SIRT / LEVAGE | K3: TOTAL GENERE
B4: Janvier | C4: =Janvier!$D$54 | D4: =Janvier!$E$54 | E4: =Janvier!$F$54 | F4: =Janvier!$I$54 | G4: =Janvier!$J$54 | H4: =Janvier!$L$54 | I4: =Janvier!$M$54 | J4: =Janvier!$K$54 | K4: =SUM(C4:J4)
B5: Février | C5: =Février!$D$54 | D5: =Février!$E$54 | E5: =Février!$F$54 | F5: =Février!$I$54 | G5: =Février!$J$54 | H5: =Février!$L$54 | I5: =Février!$M$54 | J5: =Février!$K$54 | K5: =SUM(C5:J5)
B6: Mars | C6: =Mars!$D$54 | D6: =Mars!$E$54 | E6: =Mars!$F$54 | F6: =Mars!$I$54 | G6: =Mars!$J$54 | H6: =Mars!$L$54 | I6: =Mars!$M$54 | J6: =Mars!$K$54 | K6: =SUM(C6:J6)
B7: Avril | C7: =Avril!$D$54 | D7: =Avril!$E$54 | E7: =Avril!$F$54 | F7: =Avril!$I$54 | G7: =Avril!$J$54 | H7: =Avril!$L$54 | I7: =Avril!$M$54 | J7: =Avril!$K$54 | K7: =SUM(C7:J7)
B8: Mai | C8: =Mai!$D$54 | D8: =Mai!$E$54 | E8: =Mai!$F$54 | F8: =Mai!$I$54 | G8: =Mai!$J$54 | H8: =Mai!$L$54 | I8: =Mai!$M$54 | J8: =Mai!$K$54 | K8: =SUM(C8:J8)
B9: Juin | C9: =Juin!$D$54 | D9: =Juin!$E$54 | E9: =Juin!$F$54 | F9: =Juin!$I$54 | G9: =Juin!$J$54 | H9: =Juin!$L$54 | I9: =Juin!$M$54 | J9: =Juin!$K$54 | K9: =SUM(C9:J9)
B10: Juillet | C10: =Juillet!$D$54 | D10: =Juillet!$E$54 | E10: =Juillet!$F$54 | F10: =Juillet!$I$54 | G10: =Juillet!$J$54 | H10: =Juillet!$L$54 | I10: =Juillet!$M$54 | J10: =Juillet!$K$54 | K10: =SUM(C10:J10)
B11: Août | C11: =Aout!$D$54 | D11: =Aout!$E$54 | E11: =Aout!$F$54 | F11: =Aout!$I$54 | G11: =Aout!$J$54 | H11: =Aout!$L$54 | I11: =Aout!$M$54 | J11: =Aout!$K$54 | K11: =SUM(C11:J11)
B12: Septembre | C12: =Septembre!$D$54 | D12: =Septembre!$E$54 | E12: =Septembre!$F$54 | F12: =Septembre!$I$54 | G12: =Septembre!$J$54 | H12: =Septembre!$L$54 | I12: =Septembre!$M$54 | J12: =Septembre!$K$54 | K12: =SUM(C12:J12)
B13: Octobre | C13: =Octobre!$D$54 | D13: =Octobre!$E$54 | E13: =Octobre!$F$54 | F13: =Octobre!$I$54 | G13: =Octobre!$J$54 | H13: =Octobre!$L$54 | I13: =Octobre!$M$54 | J13: =Octobre!$K$54 | K13: =SUM(C13:J13)
B14: Novembre | C14: =Novembre!$D$54 | D14: =Novembre!$E$54 | E14: =Novembre!$F$54 | F14: =Novembre!$I$54 | G14: =Novembre!$J$54 | H14: =Novembre!$L$54 | I14: =Novembre!$M$54 | J14: =Novembre!$K$54 | K14: =SUM(C14:J14)
B15: Décembre | C15: =Décembre!$D$54 | D15: =Décembre!$E$54 | E15: =Décembre!$F$54 | F15: =Décembre!$I$54 | G15: =Décembre!$J$54 | H15: =Décembre!$L$54 | I15: =Décembre!$M$54 | J15: =Décembre!$K$54 | K15: =SUM(C15:J15)
B16: Cumul | C16: =SUM(C4:C15) | D16: =SUM(D4:D15) | E16: =SUM(E4:E15) | F16: =SUM(F4:F15) | G16: =SUM(G4:G15) | H16: =SUM(H4:H15) | I16: =SUM(I4:I15) | J16: =SUM(J4:J15) | K16: =SUM(C16:J16)
B17: Part | C17: =C16/$K$16 | D17: =D16/$K$16 | E17: =E16/$K$16 | F17: =F16/$K$16 | G17: =G16/$K$16 | H17: =H16/$K$16 | I17: =I16/$K$16 | J17: =J16/$K$16
B20: RO Généré par Département sur Clients O&G (Après rétrocessions)
C22: Base O&G | D22: Import Maritime | E22: Hinterland | F22: Aérien | G22: Export Maritime | H22: Afritramp | I22: Meet & Greet | J22: SIRT / LEVAGE | K22: TOTAL GENERE
B23: Janvier | K23: =K24/K4
C24: 58198 | D24: =D23*D4 | E24: =E23*E4 | F24: =F23*F4 | G24: =G23*G4 | H24: =H23*H4 | I24: =I23*I4 | J24: =J23*J4 | K24: =SUM(C24:J24)
B25: Février | K25: =K26/K5
C26: 76867 | D26: =D25*D5 | E26: =E25*E5 | F26: =F25*F5 | G26: =G25*G5 | H26: =H25*H5 | I26: =I25*I5 | J26: =J25*J5 | K26: =SUM(C26:J26)
B27: Mars | K27: =K28/K6
C28: 37939 | D28: =D27*D6 | E28: =E27*E6 | F28: =F27*F6 | G28: =G27*G6 | H28: =H27*H6 | I28: =I27*I6 | J28: =J27*J6 | K28: =SUM(C28:J28)
B29: Avril | K29: =K30/#REF!
C30: 39815 | D30: =D29*#REF! | E30: =E29*#REF! | F30: =F29*#REF! | G30: =G29*#REF! | H30: =H29*#REF! | I30: =I29*#REF! | J30: =J29*#REF! | K30: =SUM(C30:J30)
B31: Mai | K31: =K32/#REF!
C32: 59120 | D32: =D31*#REF! | E32: =E31*#REF! | F32: =F31*#REF! | G32: =G31*#REF! | H32: =H31*#REF! | I32: =I31*#REF! | J32: =J31*#REF! | K32: =SUM(C32:J32)
B33: Juin | K33: =K34/#REF!
C34: 44460 | D34: =D33*#REF! | E34: =E33*#REF! | F34: =F33*#REF! | G34: =G33*#REF! | H34: =H33*#REF! | I34: =I33*#REF! | J34: =J33*#REF! | K34: =SUM(C34:J34)
B35: Juillet | K35: =K36/#REF!
C36: 19556 | D36: =D35*#REF! | E36: =E35*#REF! | F36: =F35*#REF! | G36: =G35*#REF! | H36: =H35*#REF! | I36: =I35*#REF! | J36: =J35*#REF! | K36: =SUM(C36:J36)
B37: Août | K37: =K38/#REF!
C38: 41107 | D38: =D37*#REF! | E38: =E37*#REF! | F38: =F37*#REF! | G38: =G37*#REF! | H38: =H37*#REF! | I38: =I37*#REF! | J38: =J37*#REF! | K38: =SUM(C38:J38)
B39: Septembre | K39: =K40/#REF!
C40: 37394 | D40: =D39*#REF! | E40: =E39*#REF! | F40: =F39*#REF! | G40: =G39*#REF! | H40: =H39*#REF! | I40: =I39*#REF! | J40: =J39*#REF! | K40: =SUM(C40:J40)
B41: Octobre | K41: =K42/#REF!
C42: 70199 | D42: =D41*#REF! | E42: =E41*#REF! | F42: =F41*#REF! | G42: =G41*#REF! | H42: =H41*#REF! | I42: =I41*#REF! | J42: =J41*#REF! | K42: =SUM(C42:J42)
B43: Novembre | K43: =K44/#REF!
C44: 41339 | D44: =D43*#REF! | E44: =E43*#REF! | F44: =F43*#REF! | G44: =G43*#REF! | H44: =H43*#REF! | I44: =I43*#REF! | J44: =J43*#REF! | K44: =SUM(C44:J44)
...

Sheet Cumul annuel
A1: 1 | B1: CAP Cumulé 2021 | O1: VARIATION R 23 sur B23 | AS1: VARIATION R 16 sur PFA 8 + 4 2016
B2: BASE | E2: CA GENERE | N2: GW Margin EURO | O2: R23 Cumulé | S2: Variation Réel 23 Cumulé / B23 Prorata | X2: Variation Réel 23 CUMULE / B23 COMPLET | AD2: Variation Réel 15 CUMULE / PFA 4+ 8 2015 COMPLET | AI2: Variation Réel 15 CUMULE / PFA 8+ 4 2015 COMPLET | AN2: Variation Réel 15 CUMULE / PFA 8+ 4 2015 Prorata | AS2: Variation B 16 PFA 4 + 8 / B16 COMPLET | AX2: Variation Reel 2016 / B 16 PFA 8 + 4 Prorata | BC2: Variation Reel 2016 / B 16 PFA 8 + 4 COMPLET
B3: LOYERS | C3: Plog & Divers | D3: Total BASE | E3: IMAR | F3: HINT | G3: IAER | H3: EAER | I3: AERIEN | J3: EXPORT | K3: SIRT (dédié) | L3: CA Dpt Ext | M3: CA TOTAL GENERE PAR CLIENT | O3: Sources revenus | P3: R23 Loyer | Q3: R21 Log & divers | R3: TOTAL R23 | S3: B20 Loyer | T3: B20 Log & divers | U3: Budget 2023 | V3: VAR (FCFA) | W3: Var (%) | X3: B23 Loyer | Y3: B23Log & divers | Z3: Budget 2023 | AA3: VAR (FCFA) | AB3: Var (%) | AD3: PFA Loyer | AE3: PFA Log & divers | AF3: PFA 4 + 8 2015 | AG3: VAR (FCFA) | AH3: Var (%) | AI3: PFA Loyer | AJ3: PFA Log & divers | AK3: PFA 8 + 4 2015 | AL3: VAR (FCFA) | AM3: Var (%) | AN3: PFA Loyer | AO3: PFA Log & divers | AP3: PFA 8 + 4 2015 | AQ3: VAR (FCFA) | AR3: Var (%) | AS3: PFA Loyer | AT3: PFA Log & divers | AU3: PFA 4 + 8 2016 | AV3: VAR (FCFA) | AW3: Var (%) | AX3: PFA Loyer | AY3: PFA Log & divers | AZ3: PFA 4 + 8 2016 | BA3: VAR (FCFA) | BB3: Var (%) | BC3: PFA Loyer | BD3: PFA Log & divers | BE3: PFA 4 + 8 2016 | BF3: VAR (FCFA) | BG3: Var (%)
A4: NAVITRANS (ex CIAM) | B4: =Janvier!B4+Février!B4+Mars!B4+Avril!B4+Mai!B4+Juin!B4+Juillet!B4+Aout!B4+Septembre!B4+Octobre!B4+Novembre!B4+Décembre!B4 | C4: =Janvier!C4+Février!C4+Mars!C4+Avril!C4+Mai!C4+Juin!C4+Juillet!C4+Aout!C4+Septembre!C4+Octobre!C4+Novembre!C4+Décembre!C4 | D4: =Janvier!D4+Février!D4+Mars!D4+Avril!D4+Mai!D4+Juin!D4+Juillet!D4+Aout!D4+Septembre!D4+Octobre!D4+Novembre!D4+Décembre!D4 | E4: =Janvier!E4+Février!E4+Mars!E4+Avril!E4+Mai!E4+Juin!E4+Juillet!E4+Aout!E4+Septembre!E4+Octobre!E4+Novembre!E4+Décembre!E4 | F4: =Janvier!F4+Février!F4+Mars!F4+Avril!F4+Mai!F4+Juin!F4+Juillet!F4+Aout!F4+Septembre!F4+Octobre!F4+Novembre!F4+Décembre!F4 | G4: =Janvier!G4+Février!G4+Mars!G4+Avril!G4+Mai!G4+Juin!G4+Juillet!G4+Aout!G4+Septembre!G4+Octobre!G4+Novembre!G4+Décembre!G4 | H4: =Janvier!H4+Février!H4+Mars!H4+Avril!H4+Mai!H4+Juin!H4+Juillet!H4+Aout!H4+Septembre!H4+Octobre!H4+Novembre!H4+Décembre!H4 | I4: =Janvier!I4+Février!I4+Mars!I4+Avril!I4+Mai!I4+Juin!I4+Juillet!I4+Aout!I4+Septembre!I4+Octobre!I4+Novembre!I4+Décembre!I4 | J4: =Janvier!J4+Février!J4+Mars!J4+Avril!J4+Mai!J4+Juin!J4+Juillet!J4+Aout!J4+Septembre!J4+Octobre!J4+Novembre!J4+Décembre!J4 | L4: =SUM(E4:F4,I4:K4) | M4: =L4+D4 | N4: =M4/655.957 | O4: =A4 | P4: =B4 | Q4: =C4 | R4: =D4 | S4: =X4/12*$A$1 | T4: =Y4/12*$A$1 | U4: 833333 | V4: =$R4-U4 | W4: =R4/U4-1 | X4: 0 | Y4: 15000000 | Z4: =Y4+X4 | AA4: =R4-Z4 | AB4: =R4/Z4-1 | AC4: =Z4/$Z$57 | AD4: 0 | AE4: =AF4-AD4 | AF4: 0 | AG4: =R4-AF4 | AH4: =R4/AF4-1 | AI4: 0 | AJ4: =AK4-AI4 | AK4: 0 | AL4: =R4-AK4 | AM4: 0 | AN4: =AI4/12*$A$1 | AO4: =AJ4/12*$A$1 | AP4: =AO4+AN4 | AQ4: =R4-AP4 | AR4: 0 | AT4: 20000000 | AU4: =AT4+AS4 | AV4: =AU4-Z4 | AW4: =AU4/Z4-1 | AX4: =BC4/12*$A$1 | AY4: =BD4/12*$A$1 | AZ4: =AY4+AX4 | BA4: =$R4-AZ4 | BB4: =$R4/AZ4-1 | BD4: 30000000 | BE4: =BD4+BC4 | BF4: =$R4-BE4 | BG4: =$R4/BE4-1
A5: DRIL QUIP | B5: =Janvier!B5+Février!B5+Mars!B5+Avril!B5+Mai!B5+Juin!B5+Juillet!B5+Aout!B5+Septembre!B5+Octobre!B5+Novembre!B5+Décembre!B5 | C5: =Janvier!C5+Février!C5+Mars!C5+Avril!C5+Mai!C5+Juin!C5+Juillet!C5+Aout!C5+Septembre!C5+Octobre!C5+Novembre!C5+Décembre!C5 | D5: =Janvier!D5+Février!D5+Mars!D5+Avril!D5+Mai!D5+Juin!D5+Juillet!D5+Aout!D5+Septembre!D5+Octobre!D5+Novembre!D5+Décembre!D5 | E5: =Janvier!E5+Février!E5+Mars!E5+Avril!E5+Mai!E5+Juin!E5+Juillet!E5+Aout!E5+Septembre!E5+Octobre!E5+Novembre!E5+Décembre!E5 | F5: =Janvier!F5+Février!F5+Mars!F5+Avril!F5+Mai!F5+Juin!F5+Juillet!F5+Aout!F5+Septembre!F5+Octobre!F5+Novembre!F5+Décembre!F5 | G5: =Janvier!G5+Février!G5+Mars!G5+Avril!G5+Mai!G5+Juin!G5+Juillet!G5+Aout!G5+Septembre!G5+Octobre!G5+Novembre!G5+Décembre!G5 | H5: =Janvier!H5+Février!H5+Mars!H5+Avril!H5+Mai!H5+Juin!H5+Juillet!H5+Aout!H5+Septembre!H5+Octobre!H5+Novembre!H5+Décembre!H5 | I5: =Janvier!I5+Février!I5+Mars!I5+Avril!I5+Mai!I5+Juin!I5+Juillet!I5+Aout!I5+Septembre!I5+Octobre!I5+Novembre!I5+Décembre!I5 | J5: =Janvier!J5+Février!J5+Mars!J5+Avril!J5+Mai!J5+Juin!J5+Juillet!J5+Aout!J5+Septembre!J5+Octobre!J5+Novembre!J5+Décembre!J5 | L5: =SUM(E5:F5,I5:K5) | M5: =L5+D5 | N5: =M5/655.957 | O5: =A5 | P5: =B5 | Q5: =C5 | R5: =D5 | S5: =X5/12*$A$1 | T5: =Y5/12*$A$1 | U5: 0 | V5: =$R5-U5 | W5: =R5/U5-1 | X5: 0 | Y5: 0 | Z5: =Y5+X5 | AA5: =R5-Z5 | AB5: =R5/Z5-1 | AC5: =Z5/$Z$57 | AE5: =AF5-AD5 | AF5: 220000 | AG5: =R5-AF5 | AH5: =R5/AF5-1 | AJ5: =AK5-AI5 | AK5: 220000 | AL5: =R5-AK5 | AM5: =R5/AK5-1 | AN5: =AI5/12*$A$1 | AO5: =AJ5/12*$A$1 | AP5: =AO5+AN5 | AQ5: =R5-AP5 | AR5: =R5/AP5-1 | AU5: =AT5+AS5 | AV5: =AU5-Z5 | AW5: =AU5/Z5-1 | AX5: =BC5/12*$A$1 | AY5: =BD5/12*$A$1 | AZ5: =AY5+AX5 | BA5: =$R5-AZ5 | BB5: =$R5/AZ5-1 | BE5: =BD5+BC5 | BF5: =$R5-BE5 | BG5: =$R5/BE5-1
A6: BORR GERD | B6: =Janvier!B6+Février!B6+Mars!B6+Avril!B6+Mai!B6+Juin!B6+Juillet!B6+Aout!B6+Septembre!B6+Octobre!B6+Novembre!B6+Décembre!B6 | C6: =Janvier!C6+Février!C6+Mars!C6+Avril!C6+Mai!C6+Juin!C6+Juillet!C6+Aout!C6+Septembre!C6+Octobre!C6+Novembre!C6+Décembre!C6 | D6: =Janvier!D6+Février!D6+Mars!D6+Avril!D6+Mai!D6+Juin!D6+Juillet!D6+Aout!D6+Septembre!D6+Octobre!D6+Novembre!D6+Décembre!D6 | E6: =Janvier!E6+Février!E6+Mars!E6+Avril!E6+Mai!E6+Juin!E6+Juillet!E6+Aout!E6+Septembre!E6+Octobre!E6+Novembre!E6+Décembre!E6 | F6: =Janvier!F6+Février!F6+Mars!F6+Avril!F6+Mai!F6+Juin!F6+Juillet!F6+Aout!F6+Septembre!F6+Octobre!F6+Novembre!F6+Décembre!F6 | G6: =Janvier!G6+Février!G6+Mars!G6+Avril!G6+Mai!G6+Juin!G6+Juillet!G6+Aout!G6+Septembre!G6+Octobre!G6+Novembre!G6+Décembre!G6 | H6: =Janvier!H6+Février!H6+Mars!H6+Avril!H6+Mai!H6+Juin!H6+Juillet!H6+Aout!H6+Septembre!H6+Octobre!H6+Novembre!H6+Décembre!H6 | I6: =Janvier!I6+Février!I6+Mars!I6+Avril!I6+Mai!I6+Juin!I6+Juillet!I6+Aout!I6+Septembre!I6+Octobre!I6+Novembre!I6+Décembre!I6 | J6: =Janvier!J6+Février!J6+Mars!J6+Avril!J6+Mai!J6+Juin!J6+Juillet!J6+Aout!J6+Septembre!J6+Octobre!J6+Novembre!J6+Décembre!J6 | L6: =SUM(E6:F6,I6:K6) | M6: =L6+D6 | N6: =M6/655.957 | O6: =A6 | P6: =B6 | Q6: =C6 | R6: =D6 | S6: =X6/12*$A$1 | T6: =Y6/12*$A$1 | U6: 0 | V6: =$R6-U6 | W6: =R6/U6-1 | X6: 0 | Y6: 10000000 | Z6: =Y6+X6 | AA6: =R6-Z6 | AB6: =R6/Z6-1 | AC6: =Z6/$Z$57 | AD6: 105000000 | AE6: =AF6-AD6 | AF6: 250000000 | AG6: =R6-AF6 | AH6: =R6/AF6-1 | AI6: 105000000 | AJ6: =AK6-AI6 | AK6: 165000000 | AL6: =R6-AK6 | AM6: =R6/AK6-1 | AN6: =AI6/12*$A$1 | AO6: =AJ6/12*$A$1 | AP6: =AO6+AN6 | AQ6: =R6-AP6 | AR6: =R6/AP6-1 | AS6: =8500000*12 | AT6: =28000000+6000000*5 | AU6: =AT6+AS6 | AV6: =AU6-Z6 | AW6: =AU6/Z6-1 | AX6: =BC6/12*$A$1 | AY6: =BD6/12*$A$1 | AZ6: =AY6+AX6 | BA6: =$R6-AZ6 | BB6: =$R6/AZ6-1 | BC6: =8500000*12+600000 | BD6: 270000000 | BE6: =BD6+BC6 | BF6: =$R6-BE6 | BG6: =$R6/BE6-1
A7: BAKER HUGHUES | B7: =Janvier!B7+Février!B7+Mars!B7+Avril!B7+Mai!B7+Juin!B7+Juillet!B7+Aout!B7+Septembre!B7+Octobre!B7+Novembre!B7+Décembre!B7 | C7: =Janvier!C7+Février!C7+Mars!C7+Avril!C7+Mai!C7+Juin!C7+Juillet!C7+Aout!C7+Septembre!C7+Octobre!C7+Novembre!C7+Décembre!C7 | D7: =Janvier!D7+Février!D7+Mars!D7+Avril!D7+Mai!D7+Juin!D7+Juillet!D7+Aout!D7+Septembre!D7+Octobre!D7+Novembre!D7+Décembre!D7 | E7: =Janvier!E7+Février!E7+Mars!E7+Avril!E7+Mai!E7+Juin!E7+Juillet!E7+Aout!E7+Septembre!E7+Octobre!E7+Novembre!E7+Décembre!E7 | F7: =Janvier!F7+Février!F7+Mars!F7+Avril!F7+Mai!F7+Juin!F7+Juillet!F7+Aout!F7+Septembre!F7+Octobre!F7+Novembre!F7+Décembre!F7 | G7: =Janvier!G7+Février!G7+Mars!G7+Avril!G7+Mai!G7+Juin!G7+Juillet!G7+Aout!G7+Septembre!G7+Octobre!G7+Novembre!G7+Décembre!G7 | H7: =Janvier!H7+Février!H7+Mars!H7+Avril!H7+Mai!H7+Juin!H7+Juillet!H7+Aout!H7+Septembre!H7+Octobre!H7+Novembre!H7+Décembre!H7 | I7: =Janvier!I7+Février!I7+Mars!I7+Avril!I7+Mai!I7+Juin!I7+Juillet!I7+Aout!I7+Septembre!I7+Octobre!I7+Novembre!I7+Décembre!I7 | J7: =Janvier!J7+Février!J7+Mars!J7+Avril!J7+Mai!J7+Juin!J7+Juillet!J7+Aout!J7+Septembre!J7+Octobre!J7+Novembre!J7+Décembre!J7 | L7: =SUM(E7:F7,I7:K7) | M7: =L7+D7 | N7: =M7/655.957 | O7: =A7 | P7: =B7 | Q7: =C7 | R7: =D7 | S7: =X7/12*$A$1 | T7: =Y7/12*$A$1 | U7: 7250000 | V7: =$R7-U7 | W7: =R7/U7-1 | X7: 75000000 | Y7: 50000000 | Z7: =Y7+X7 | AA7: =R7-Z7 | AB7: =R7/Z7-1 | AC7: =Z7/$Z$57 | AD7: 86000000 | AE7: =AF7-AD7 | AF7: 140000000 | AG7: =R7-AF7 | AH7: =R7/AF7-1 | AI7: 86000000 | AJ7: =AK7-AI7 | AK7: 111000000 | AL7: =R7-AK7 | AM7: =R7/AK7-1 | AN7: =AI7/12*$A$1 | AO7: =AJ7/12*$A$1 | AP7: =AO7+AN7 | AQ7: =R7-AP7 | AR7: =R7/AP7-1 | AS7: =16833000*4 | AT7: 45000000 | AU7: =AT7+AS7 | AV7: =AU7-Z7 | AW7: =AU7/Z7-1 | AX7: =BC7/12*$A$1 | AY7: =BD7/12*$A$1 | AZ7: =AY7+AX7 | BA7: =$R7-AZ7 | BB7: =$R7/AZ7-1 | BC7: =16833000*4-2000000 | BD7: 70000000 | BE7: =BD7+BC7 | BF7: =$R7-BE7 | BG7: =$R7/BE7-1
A8: ALTERA INFRASTRUCTURE | B8: =Janvier!B8+Février!B8+Mars!B8+Avril!B8+Mai!B8+Juin!B8+Juillet!B8+Aout!B8+Septembre!B8+Octobre!B8+Novembre!B8+Décembre!B8 | C8: =Janvier!C8+Février!C8+Mars!C8+Avril!C8+Mai!C8+Juin!C8+Juillet!C8+Aout!C8+Septembre!C8+Octobre!C8+Novembre!C8+Décembre!C8 | D8: =Janvier!D8+Février!D8+Mars!D8+Avril!D8+Mai!D8+Juin!D8+Juillet!D8+Aout!D8+Septembre!D8+Octobre!D8+Novembre!D8+Décembre!D8 | E8: =Janvier!E8+Février!E8+Mars!E8+Avril!E8+Mai!E8+Juin!E8+Juillet!E8+Aout!E8+Septembre!E8+Octobre!E8+Novembre!E8+Décembre!E8 | F8: =Janvier!F8+Février!F8+Mars!F8+Avril!F8+Mai!F8+Juin!F8+Juillet!F8+Aout!F8+Septembre!F8+Octobre!F8+Novembre!F8+Décembre!F8 | G8: =Janvier!G8+Février!G8+Mars!G8+Avril!G8+Mai!G8+Juin!G8+Juillet!G8+Aout!G8+Septembre!G8+Octobre!G8+Novembre!G8+Décembre!G8 | H8: =Janvier!H8+Février!H8+Mars!H8+Avril!H8+Mai!H8+Juin!H8+Juillet!H8+Aout!H8+Septembre!H8+Octobre!H8+Novembre!H8+Décembre!H8 | I8: =Janvier!I8+Février!I8+Mars!I8+Avril!I8+Mai!I8+Juin!I8+Juillet!I8+Aout!I8+Septembre!I8+Octobre!I8+Novembre!I8+Décembre!I8 | J8: =Janvier!J8+Février!J8+Mars!J8+Avril!J8+Mai!J8+Juin!J8+Juillet!J8+Aout!J8+Septembre!J8+Octobre!J8+Novembre!J8+Décembre!J8 | L8: =SUM(E8:F8,I8:K8) | M8: =L8+D8 | N8: =M8/655.957 | O8: =A8 | P8: =B8 | Q8: =C8 | R8: =D8 | S8: =X8/12*$A$1 | T8: =Y8/12*$A$1 | U8: 0 | V8: =$R8-U8 | W8: =R8/U8-1 | X8: 0 | Y8: 0 | Z8: =Y8+X8 | AA8: =R8-Z8 | AB8: =R8/Z8-1 | AC8: =Z8/$Z$57 | AE8: =AF8-AD8 | AF8: =AC8*4901000000 | AG8: =R8-AF8 | AH8: =R8/AF8-1 | AJ8: =AK8-AI8 | AK8: 0 | AL8: =R8-AK8 | AM8: 0 | AN8: =AI8/12*$A$1 | AO8: =AJ8/12*$A$1 | AP8: =AO8+AN8 | AQ8: =R8-AP8 | AR8: 0 | AU8: =AT8+AS8 | AV8: =AU8-Z8 | AW8: =AU8/Z8-1 | AX8: =BC8/12*$A$1 | AY8: =BD8/12*$A$1 | AZ8: =AY8+AX8 | BA8: =$R8-AZ8 | BB8: =$R8/AZ8-1 | BE8: =BD8+BC8 | BF8: =$R8-BE8 | BG8: =$R8/BE8-1
A9: ICM COTE D'IVOIRE | B9: =Janvier!B9+Février!B9+Mars!B9+Avril!B9+Mai!B9+Juin!B9+Juillet!B9+Aout!B9+Septembre!B9+Octobre!B9+Novembre!B9+Décembre!B9 | C9: =Janvier!C9+Février!C9+Mars!C9+Avril!C9+Mai!C9+Juin!C9+Juillet!C9+Aout!C9+Septembre!C9+Octobre!C9+Novembre!C9+Décembre!C9 | D9: =Janvier!D9+Février!D9+Mars!D9+Avril!D9+Mai!D9+Juin!D9+Juillet!D9+Aout!D9+Septembre!D9+Octobre!D9+Novembre!D9+Décembre!D9 | E9: =Janvier!E9+Février!E9+Mars!E9+Avril!E9+Mai!E9+Juin!E9+Juillet!E9+Aout!E9+Septembre!E9+Octobre!E9+Novembre!E9+Décembre!E9 | F9: =Janvier!F9+Février!F9+Mars!F9+Avril!F9+Mai!F9+Juin!F9+Juillet!F9+Aout!F9+Septembre!F9+Octobre!F9+Novembre!F9+Décembre!F9 | G9: =Janvier!G9+Février!G9+Mars!G9+Avril!G9+Mai!G9+Juin!G9+Juillet!G9+Aout!G9+Septembre!G9+Octobre!G9+Novembre!G9+Décembre!G9 | H9: =Janvier!H9+Février!H9+Mars!H9+Avril!H9+Mai!H9+Juin!H9+Juillet!H9+Aout!H9+Septembre!H9+Octobre!H9+Novembre!H9+Décembre!H9 | I9: =Janvier!I9+Février!I9+Mars!I9+Avril!I9+Mai!I9+Juin!I9+Juillet!I9+Aout!I9+Septembre!I9+Octobre!I9+Novembre!I9+Décembre!I9 | J9: =Janvier!J9+Février!J9+Mars!J9+Avril!J9+Mai!J9+Juin!J9+Juillet!J9+Aout!J9+Septembre!J9+Octobre!J9+Novembre!J9+Décembre!J9 | L9: =SUM(E9:F9,I9:K9) | M9: =L9+D9 | N9: =M9/655.957 | O9: =A9 | P9: =B9 | Q9: =C9 | R9: =D9 | S9: =X9/12*$A$1 | T9: =Y9/12*$A$1 | U9: 0 | V9: =$R9-U9 | W9: =R9/U9-1 | Z9: =Y9+X9 | AA9: =R9-Z9 | AB9: =R9/Z9-1 | AC9: =Z9/$Z$57 | AE9: =AF9-AD9 | AF9: 3140000 | AG9: =R9-AF9 | AH9: =R9/AF9-1 | AJ9: =AK9-AI9 | AK9: 3140000 | AL9: =R9-AK9 | AM9: =R9/AK9-1 | AN9: =AI9/12*$A$1 | AO9: =AJ9/12*$A$1 | AP9: =AO9+AN9 | AQ9: =R9-AP9 | AR9: =R9/AP9-1 | AU9: =AT9+AS9 | AV9: =AU9-Z9 | AW9: =AU9/Z9-1 | AX9: =BC9/12*$A$1 | AY9: =BD9/12*$A$1 | AZ9: =AY9+AX9 | BA9: =$R9-AZ9 | BB9: =$R9/AZ9-1 | BE9: =BD9+BC9 | BF9: =$R9-BE9 | BG9: =$R9/BE9-1
A10: OILFIELD MACHINE SHOP (OMS) | B10: =Janvier!B10+Février!B10+Mars!B10+Avril!B10+Mai!B10+Juin!B10+Juillet!B10+Aout!B10+Septembre!B10+Octobre!B10+Novembre!B10+Décembre!B10 | C10: =Janvier!C10+Février!C10+Mars!C10+Avril!C10+Mai!C10+Juin!C10+Juillet!C10+Aout!C10+Septembre!C10+Octobre!C10+Novembre!C10+Décembre!C10 | D10: =Janvier!D10+Février!D10+Mars!D10+Avril!D10+Mai!D10+Juin!D10+Juillet!D10+Aout!D10+Septembre!D10+Octobre!D10+Novembre!D10+Décembre!D10 | E10: =Janvier!E10+Février!E10+Mars!E10+Avril!E10+Mai!E10+Juin!E10+Juillet!E10+Aout!E10+Septembre!E10+Octobre!E10+Novembre!E10+Décembre!E10 | F10: =Janvier!F10+Février!F10+Mars!F10+Avril!F10+Mai!F10+Juin!F10+Juillet!F10+Aout!F10+Septembre!F10+Octobre!F10+Novembre!F10+Décembre!F10 | G10: =Janvier!G10+Février!G10+Mars!G10+Avril!G10+Mai!G10+Juin!G10+Juillet!G10+Aout!G10+Septembre!G10+Octobre!G10+Novembre!G10+Décembre!G10 | H10: =Janvier!H10+Février!H10+Mars!H10+Avril!H10+Mai!H10+Juin!H10+Juillet!H10+Aout!H10+Septembre!H10+Octobre!H10+Novembre!H10+Décembre!H10 | I10: =Janvier!I10+Février!I10+Mars!I10+Avril!I10+Mai!I10+Juin!I10+Juillet!I10+Aout!I10+Septembre!I10+Octobre!I10+Novembre!I10+Décembre!I10 | J10: =Janvier!J10+Février!J10+Mars!J10+Avril!J10+Mai!J10+Juin!J10+Juillet!J10+Aout!J10+Septembre!J10+Octobre!J10+Novembre!J10+Décembre!J10 | L10: =SUM(E10:F10,I10:K10) | M10: =L10+D10 | N10: =M10/655.957 | O10: =A10 | P10: =B10 | Q10: =C10 | R10: =D10 | S10: =X10/12*$A$1 | T10: =Y10/12*$A$1 | U10: 0 | V10: =$R10-U10 | W10: =R10/U10-1 | Z10: =Y10+X10 | AA10: =R10-Z10 | AB10: =R10/Z10-1 | AC10: =Z10/$Z$57 | AE10: =AF10-AD10 | AF10: 7000000 | AG10: =R10-AF10 | AH10: =R10/AF10-1 | AJ10: =AK10-AI10 | AK10: 35000000 | AL10: =R10-AK10 | AM10: =R10/AK10-1 | AN10: =AI10/12*$A$1 | AO10: =AJ10/12*$A$1 | AP10: =AO10+AN10 | AQ10: =R10-AP10 | AR10: =R10/AP10-1 | AT10: 25000000 | AU10: =AT10+AS10 | AV10: =AU10-Z10 | AW10: =AU10/Z10-1 | AX10: =BC10/12*$A$1 | AY10: =BD10/12*$A$1 | AZ10: =AY10+AX10 | BA10: =$R10-AZ10 | BB10: =$R10/AZ10-1 | BE10: =BD10+BC10 | BF10: =$R10-BE10 | BG10: =$R10/BE10-1
A11: CNR INTERNATIONAL | B11: =Janvier!B11+Février!B11+Mars!B11+Avril!B11+Mai!B11+Juin!B11+Juillet!B11+Aout!B11+Septembre!B11+Octobre!B11+Novembre!B11+Décembre!B11 | C11: =Janvier!C11+Février!C11+Mars!C11+Avril!C11+Mai!C11+Juin!C11+Juillet!C11+Aout!C11+Septembre!C11+Octobre!C11+Novembre!C11+Décembre!C11 | D11: =Janvier!D11+Février!D11+Mars!D11+Avril!D11+Mai!D11+Juin!D11+Juillet!D11+Aout!D11+Septembre!D11+Octobre!D11+Novembre!D11+Décembre!D11 | E11: =Janvier!E11+Février!E11+Mars!E11+Avril!E11+Mai!E11+Juin!E11+Juillet!E11+Aout!E11+Septembre!E11+Octobre!E11+Novembre!E11+Décembre!E11 | F11: =Janvier!F11+Février!F11+Mars!F11+Avril!F11+Mai!F11+Juin!F11+Juillet!F11+Aout!F11+Septembre!F11+Octobre!F11+Novembre!F11+Décembre!F11 | G11: =Janvier!G11+Février!G11+Mars!G11+Avril!G11+Mai!G11+Juin!G11+Juillet!G11+Aout!G11+Septembre!G11+Octobre!G11+Novembre!G11+Décembre!G11 | H11: =Janvier!H11+Février!H11+Mars!H11+Avril!H11+Mai!H11+Juin!H11+Juillet!H11+Aout!H11+Septembre!H11+Octobre!H11+Novembre!H11+Décembre!H11 | I11: =Janvier!I11+Février!I11+Mars!I11+Avril!I11+Mai!I11+Juin!I11+Juillet!I11+Aout!I11+Septembre!I11+Octobre!I11+Novembre!I11+Décembre!I11 | J11: =Janvier!J11+Février!J11+Mars!J11+Avril!J11+Mai!J11+Juin!J11+Juillet!J11+Aout!J11+Septembre!J11+Octobre!J11+Novembre!J11+Décembre!J11 | L11: =SUM(E11:F11,I11:K11) | M11: =L11+D11 | N11: =M11/655.957 | O11: =A11 | P11: =B11 | Q11: =C11 | R11: =D11 | S11: =X11/12*$A$1 | T11: =Y11/12*$A$1 | U11: 12916667 | V11: =$R11-U11 | W11: =R11/U11-1 | X11: 0 | Y11: 70000000 | Z11: =Y11+X11 | AA11: =R11-Z11 | AB11: =R11/Z11-1 | AC11: =Z11/$Z$57 | AD11: 530000000 | AE11: =AF11-AD11 | AF11: =1100000000 | AG11: =R11-AF11 | AH11: =R11/AF11-1 | AI11: 530000000 | AJ11: =AK11-AI11 | AK11: 980000000 | AL11: =R11-AK11 | AM11: =R11/AK11-1 | AN11: =AI11/12*$A$1 | AO11: =AJ11/12*$A$1 | AP11: =AO11+AN11 | AQ11: =R11-AP11 | AR11: =R11/AP11-1 | AS11: =33795000*12 | AT11: =125000000*2 | AU11: =AT11+AS11 | AV11: =AU11-Z11 | AW11: =AU11/Z11-1 | AX11: =BC11/12*$A$1 | AY11: =BD11/12*$A$1 | AZ11: =AY11+AX11 | BA11: =$R11-AZ11 | BB11: =$R11/AZ11-1 | BC11: =33795000*12 | BD11: 450000000 | BE11: =BD11+BC11 | BF11: =$R11-BE11 | BG11: =$R11/BE11-1
A12: DIVERS CLIENTS | B12: =Janvier!B12+Février!B12+Mars!B12+Avril!B12+Mai!B12+Juin!B12+Juillet!B12+Aout!B12+Septembre!B12+Octobre!B12+Novembre!B12+Décembre!B12 | C12: =Janvier!C12+Février!C12+Mars!C12+Avril!C12+Mai!C12+Juin!C12+Juillet!C12+Aout!C12+Septembre!C12+Octobre!C12+Novembre!C12+Décembre!C12 | D12: =Janvier!D12+Février!D12+Mars!D12+Avril!D12+Mai!D12+Juin!D12+Juillet!D12+Aout!D12+Septembre!D12+Octobre!D12+Novembre!D12+Décembre!D12 | E12: =Janvier!E12+Février!E12+Mars!E12+Avril!E12+Mai!E12+Juin!E12+Juillet!E12+Aout!E12+Septembre!E12+Octobre!E12+Novembre!E12+Décembre!E12 | F12: =Janvier!F12+Février!F12+Mars!F12+Avril!F12+Mai!F12+Juin!F12+Juillet!F12+Aout!F12+Septembre!F12+Octobre!F12+Novembre!F12+Décembre!F12 | G12: =Janvier!G12+Février!G12+Mars!G12+Avril!G12+Mai!G12+Juin!G12+Juillet!G12+Aout!G12+Septembre!G12+Octobre!G12+Novembre!G12+Décembre!G12 | H12: =Janvier!H12+Février!H12+Mars!H12+Avril!H12+Mai!H12+Juin!H12+Juillet!H12+Aout!H12+Septembre!H12+Octobre!H12+Novembre!H12+Décembre!H12 | I12: =Janvier!I12+Février!I12+Mars!I12+Avril!I12+Mai!I12+Juin!I12+Juillet!I12+Aout!I12+Septembre!I12+Octobre!I12+Novembre!I12+Décembre!I12 | J12: =Janvier!J12+Février!J12+Mars!J12+Avril!J12+Mai!J12+Juin!J12+Juillet!J12+Aout!J12+Septembre!J12+Octobre!J12+Novembre!J12+Décembre!J12 | L12: =SUM(E12:F12,I12:K12) | M12: =L12+D12 | N12: =M12/655.957 | O12: =A12 | P12: =B12 | Q12: =C12 | R12: =D12 | S12: =X12/12*$A$1 | T12: =Y12/12*$A$1 | U12: 27957000 | V12: =$R12-U12 | W12: =R12/U12-1 | X12: 0 | Y12: 200000000 | Z12: =Y12+X12 | AA12: =R12-Z12 | AB12: =R12/Z12-1 | AC12: =Z12/$Z$57 | AE12: =AF12-AD12 | AF12: 65000000 | AG12: =R12-AF12 | AH12: =R12/AF12-1 | AJ12: =AK12-AI12 | AK12: 110000000 | AL12: =R12-AK12 | AM12: =R12/AK12-1 | AN12: =AI12/12*$A$1 | AO12: =AJ12/12*$A$1 | AP12: =AO12+AN12 | AQ12: =R12-AP12 | AR12: =R12/AP12-1 | AT12: 475000000 | AU12: =AT12+AS12 | AV12: =AU12-Z12 | AW12: =AU12/Z12-1 | AX12: =BC12/12*$A$1 | AY12: =BD12/12*$A$1 | AZ12: =AY12+AX12 | BA12: =$R12-AZ12 | BB12: =$R12/AZ12-1 | BD12: 42000000 | BE12: =BD12+BC12 | BF12: =$R12-BE12 | BG12: =$R12/BE12-1
A13: CNR - ICM CONTRAT BATEAU SURFER | B13: =Janvier!B13+Février!B13+Mars!B13+Avril!B13+Mai!B13+Juin!B13+Juillet!B13+Aout!B13+Septembre!B13+Octobre!B13+Novembre!B13+Décembre!B13 | C13: =Janvier!C13+Février!C13+Mars!C13+Avril!C13+Mai!C13+Juin!C13+Juillet!C13+Aout!C13+Septembre!C13+Octobre!C13+Novembre!C13+Décembre!C13 | D13: =Janvier!D13+Février!D13+Mars!D13+Avril!D13+Mai!D13+Juin!D13+Juillet!D13+Aout!D13+Septembre!D13+Octobre!D13+Novembre!D13+Décembre!D13 | E13: =Janvier!E13+Février!E13+Mars!E13+Avril!E13+Mai!E13+Juin!E13+Juillet!E13+Aout!E13+Septembre!E13+Octobre!E13+Novembre!E13+Décembre!E13 | F13: =Janvier!F13+Février!F13+Mars!F13+Avril!F13+Mai!F13+Juin!F13+Juillet!F13+Aout!F13+Septembre!F13+Octobre!F13+Novembre!F13+Décembre!F13 | G13: =Janvier!G13+Février!G13+Mars!G13+Avril!G13+Mai!G13+Juin!G13+Juillet!G13+Aout!G13+Septembre!G13+Octobre!G13+Novembre!G13+Décembre!G13 | H13: =Janvier!H13+Février!H13+Mars!H13+Avril!H13+Mai!H13+Juin!H13+Juillet!H13+Aout!H13+Septembre!H13+Octobre!H13+Novembre!H13+Décembre!H13 | I13: =Janvier!I13+Février!I13+Mars!I13+Avril!I13+Mai!I13+Juin!I13+Juillet!I13+Aout!I13+Septembre!I13+Octobre!I13+Novembre!I13+Décembre!I13 | J13: =Janvier!J13+Février!J13+Mars!J13+Avril!J13+Mai!J13+Juin!J13+Juillet!J13+Aout!J13+Septembre!J13+Octobre!J13+Novembre!J13+Décembre!J13 | L13: =SUM(E13:F13,I13:K13) | M13: =L13+D13 | N13: =M13/655.957 | O13: =A13 | P13: =B13 | Q13: =C13 | R13: =D13 | S13: =X13/12*$A$1 | T13: =Y13/12*$A$1 | U13: 0 | V13: =$R13-U13 | W13: =R13/U13-1 | X13: 0 | Y13: 0 | Z13: =Y13+X13 | AA13: =R13-Z13 | AB13: =R13/Z13-1 | AC13: =Z13/$Z$57 | AE13: =AF13-AD13 | AF13: =AC13*4901000000 | AG13: =R13-AF13 | AH13: =R13/AF13-1 | AJ13: =AK13-AI13 | AK13: 0 | AL13: =R13-AK13 | AM13: 0 | AN13: =AI13/12*$A$1 | AO13: =AJ13/12*$A$1 | AP13: =AO13+AN13 | AQ13: =R13-AP13 | AR13: 0 | AU13: =AT13+AS13 | AV13: =AU13-Z13 | AW13: =AU13/Z13-1 | AX13: =BC13/12*$A$1 | AY13: =BD13/12*$A$1 | AZ13: =AY13+AX13 | BA13: =$R13-AZ13 | BB13: =$R13/AZ13-1 | BE13: =BD13+BC13 | BF13: =$R13-BE13 | BG13: =$R13/BE13-1
A14: PETRO DISTRIBUTIONS | B14: =Janvier!B14+Février!B14+Mars!B14+Avril!B14+Mai!B14+Juin!B14+Juillet!B14+Aout!B14+Septembre!B14+Octobre!B14+Novembre!B14+Décembre!B14 | C14: =Janvier!C14+Février!C14+Mars!C14+Avril!C14+Mai!C14+Juin!C14+Juillet!C14+Aout!C14+Septembre!C14+Octobre!C14+Novembre!C14+Décembre!C14 | D14: =Janvier!D14+Février!D14+Mars!D14+Avril!D14+Mai!D14+Juin!D14+Juillet!D14+Aout!D14+Septembre!D14+Octobre!D14+Novembre!D14+Décembre!D14 | E14: =Janvier!E14+Février!E14+Mars!E14+Avril!E14+Mai!E14+Juin!E14+Juillet!E14+Aout!E14+Septembre!E14+Octobre!E14+Novembre!E14+Décembre!E14 | F14: =Janvier!F14+Février!F14+Mars!F14+Avril!F14+Mai!F14+Juin!F14+Juillet!F14+Aout!F14+Septembre!F14+Octobre!F14+Novembre!F14+Décembre!F14 | G14: =Janvier!G14+Février!G14+Mars!G14+Avril!G14+Mai!G14+Juin!G14+Juillet!G14+Aout!G14+Septembre!G14+Octobre!G14+Novembre!G14+Décembre!G14 | H14: =Janvier!H14+Février!H14+Mars!H14+Avril!H14+Mai!H14+Juin!H14+Juillet!H14+Aout!H14+Septembre!H14+Octobre!H14+Novembre!H14+Décembre!H14 | I14: =Janvier!I14+Février!I14+Mars!I14+Avril!I14+Mai!I14+Juin!I14+Juillet!I14+Aout!I14+Septembre!I14+Octobre!I14+Novembre!I14+Décembre!I14 | J14: =Janvier!J14+Février!J14+Mars!J14+Avril!J14+Mai!J14+Juin!J14+Juillet!J14+Aout!J14+Septembre!J14+Octobre!J14+Novembre!J14+Décembre!J14 | L14: =SUM(E14:F14,I14:K14) | M14: =L14+D14 | N14: =M14/655.957 | O14: =A14 | P14: =B14 | Q14: =C14 | R14: =D14 | S14: =X14/12*$A$1 | T14: =Y14/12*$A$1 | U14: 2000 | V14: =$R14-U14 | W14: =R14/U14-1 | Z14: =Y14+X14 | AA14: =R14-Z14 | AB14: =R14/Z14-1 | AC14: =Z14/$Z$57 | AD14: 50000000 | AE14: =AF14-AD14 | AF14: 100000000 | AG14: =R14-AF14 | AH14: =R14/AF14-1 | AJ14: =AK14-AI14 | AL14: =R14-AK14 | AM14: 0 | AN14: =AI14/12*$A$1 | AO14: =AJ14/12*$A$1 | AP14: =AO14+AN14 | AQ14: =R14-AP14 | AR14: 0 | AU14: =AT14+AS14 | AV14: =AU14-Z14 | AW14: =AU14/Z14-1 | AX14: =BC14/12*$A$1 | AY14: =BD14/12*$A$1 | AZ14: =AY14+AX14 | BA14: =$R14-AZ14 | BB14: =$R14/AZ14-1 | BE14: =BD14+BC14 | BF14: =$R14-BE14 | BG14: =$R14/BE14-1
A15: EXPRO GROUP | B15: =Janvier!B15+Février!B15+Mars!B15+Avril!B15+Mai!B15+Juin!B15+Juillet!B15+Aout!B15+Septembre!B15+Octobre!B15+Novembre!B15+Décembre!B15 | C15: =Janvier!C15+Février!C15+Mars!C15+Avril!C15+Mai!C15+Juin!C15+Juillet!C15+Aout!C15+Septembre!C15+Octobre!C15+Novembre!C15+Décembre!C15 | D15: =Janvier!D15+Février!D15+Mars!D15+Avril!D15+Mai!D15+Juin!D15+Juillet!D15+Aout!D15+Septembre!D15+Octobre!D15+Novembre!D15+Décembre!D15 | E15: =Janvier!E15+Février!E15+Mars!E15+Avril!E15+Mai!E15+Juin!E15+Juillet!E15+Aout!E15+Septembre!E15+Octobre!E15+Novembre!E15+Décembre!E15 | F15: =Janvier!F15+Février!F15+Mars!F15+Avril!F15+Mai!F15+Juin!F15+Juillet!F15+Aout!F15+Septembre!F15+Octobre!F15+Novembre!F15+Décembre!F15 | G15: =Janvier!G15+Février!G15+Mars!G15+Avril!G15+Mai!G15+Juin!G15+Juillet!G15+Aout!G15+Septembre!G15+Octobre!G15+Novembre!G15+Décembre!G15 | H15: =Janvier!H15+Février!H15+Mars!H15+Avril!H15+Mai!H15+Juin!H15+Juillet!H15+Aout!H15+Septembre!H15+Octobre!H15+Novembre!H15+Décembre!H15 | I15: =Janvier!I15+Février!I15+Mars!I15+Avril!I15+Mai!I15+Juin!I15+Juillet!I15+Aout!I15+Septembre!I15+Octobre!I15+Novembre!I15+Décembre!I15 | J15: =Janvier!J15+Février!J15+Mars!J15+Avril!J15+Mai!J15+Juin!J15+Juillet!J15+Aout!J15+Septembre!J15+Octobre!J15+Novembre!J15+Décembre!J15 | L15: =SUM(E15:F15,I15:K15) | M15: =L15+D15 | N15: =M15/655.957 | O15: =A15 | P15: =B15 | Q15: =C15 | R15: =D15 | S15: =X15/12*$A$1 | T15: =Y15/12*$A$1 | U15: 833000 | V15: =$R15-U15 | W15: =R15/U15-1 | X15: 0 | Y15: 0 | Z15: =Y15+X15 | AA15: =R15-Z15 | AB15: =R15/Z15-1 | AC15: =Z15/$Z$57 | AD15: 70000000 | AE15: =AF15-AD15 | AF15: 78000000 | AG15: =R15-AF15 | AH15: =R15/AF15-1 | AI15: 70000000 | AJ15: =AK15-AI15 | AK15: 78000000 | AL15: =R15-AK15 | AM15: =R15/AK15-1 | AN15: =AI15/12*$A$1 | AO15: =AJ15/12*$A$1 | AP15: =AO15+AN15 | AQ15: =R15-AP15 | AR15: =R15/AP15-1 | AS15: =4784000*2+5076000*10 | AT15: 40000000 | AU15: =AT15+AS15 | AV15: =AU15-Z15 | AW15: =AU15/Z15-1 | AX15: =BC15/12*$A$1 | AY15: =BD15/12*$A$1 | AZ15: =AY15+AX15 | BA15: =$R15-AZ15 | BB15: =$R15/AZ15-1 | BC15: 60000000 | BD15: 70000000 | BE15: =BD15+BC15 | BF15: =$R15-BE15 | BG15: =$R15/BE15-1
A16: SUPERMARITIME | B16: =Janvier!B16+Février!B16+Mars!B16+Avril!B16+Mai!B16+Juin!B16+Juillet!B16+Aout!B16+Septembre!B16+Octobre!B16+Novembre!B16+Décembre!B16 | C16: =Janvier!C16+Février!C16+Mars!C16+Avril!C16+Mai!C16+Juin!C16+Juillet!C16+Aout!C16+Septembre!C16+Octobre!C16+Novembre!C16+Décembre!C16 | D16: =Janvier!D16+Février!D16+Mars!D16+Avril!D16+Mai!D16+Juin!D16+Juillet!D16+Aout!D16+Septembre!D16+Octobre!D16+Novembre!D16+Décembre!D16 | E16: =Janvier!E16+Février!E16+Mars!E16+Avril!E16+Mai!E16+Juin!E16+Juillet!E16+Aout!E16+Septembre!E16+Octobre!E16+Novembre!E16+Décembre!E16 | F16: =Janvier!F16+Février!F16+Mars!F16+Avril!F16+Mai!F16+Juin!F16+Juillet!F16+Aout!F16+Septembre!F16+Octobre!F16+Novembre!F16+Décembre!F16 | G16: =Janvier!G16+Février!G16+Mars!G16+Avril!G16+Mai!G16+Juin!G16+Juillet!G16+Aout!G16+Septembre!G16+Octobre!G16+Novembre!G16+Décembre!G16 | H16: =Janvier!H16+Février!H16+Mars!H16+Avril!H16+Mai!H16+Juin!H16+Juillet!H16+Aout!H16+Septembre!H16+Octobre!H16+Novembre!H16+Décembre!H16 | I16: =Janvier!I16+Février!I16+Mars!I16+Avril!I16+Mai!I16+Juin!I16+Juillet!I16+Aout!I16+Septembre!I16+Octobre!I16+Novembre!I16+Décembre!I16 | J16: =Janvier!J16+Février!J16+Mars!J16+Avril!J16+Mai!J16+Juin!J16+Juillet!J16+Aout!J16+Septembre!J16+Octobre!J16+Novembre!J16+Décembre!J16 | L16: =SUM(E16:F16,I16:K16) | M16: =L16+D16 | N16: =M16/655.957 | O16: =A16 | P16: =B16 | Q16: =C16 | R16: =D16 | S16: =X16/12*$A$1 | T16: =Y16/12*$A$1 | U16: 165000 | V16: =$R16-U16 | W16: =R16/U16-1 | Z16: =Y16+X16 | AA16: =R16-Z16 | AB16: =R16/Z16-1 | AC16: =Z16/$Z$57 | AE16: =AF16-AD16 | AF16: =AC16*4901000000 | AG16: =R16-AF16 | AH16: =R16/AF16-1 | AJ16: =AK16-AI16 | AK16: 0 | AL16: =R16-AK16 | AM16: 0 | AN16: =AI16/12*$A$1 | AO16: =AJ16/12*$A$1 | AP16: =AO16+AN16 | AQ16: =R16-AP16 | AR16: 0 | AU16: =AT16+AS16 | AV16: =AU16-Z16 | AW16: =AU16/Z16-1 | AX16: =BC16/12*$A$1 | AY16: =BD16/12*$A$1 | AZ16: =AY16+AX16 | BA16: =$R16-AZ16 | BB16: =$R16/AZ16-1 | BE16: =BD16+BC16 | BF16: =$R16-BE16 | BG16: =$R16/BE16-1
A17: FOXTROT INTERNATIONAL | B17: =Janvier!B17+Février!B17+Mars!B17+Avril!B17+Mai!B17+Juin!B17+Juillet!B17+Aout!B17+Septembre!B17+Octobre!B17+Novembre!B17+Décembre!B17 | C17: =Janvier!C17+Février!C17+Mars!C17+Avril!C17+Mai!C17+Juin!C17+Juillet!C17+Aout!C17+Septembre!C17+Octobre!C17+Novembre!C17+Décembre!C17 | D17: =Janvier!D17+Février!D17+Mars!D17+Avril!D17+Mai!D17+Juin!D17+Juillet!D17+Aout!D17+Septembre!D17+Octobre!D17+Novembre!D17+Décembre!D17 | E17: =Janvier!E17+Février!E17+Mars!E17+Avril!E17+Mai!E17+Juin!E17+Juillet!E17+Aout!E17+Septembre!E17+Octobre!E17+Novembre!E17+Décembre!E17 | F17: =Janvier!F17+Février!F17+Mars!F17+Avril!F17+Mai!F17+Juin!F17+Juillet!F17+Aout!F17+Septembre!F17+Octobre!F17+Novembre!F17+Décembre!F17 | G17: =Janvier!G17+Février!G17+Mars!G17+Avril!G17+Mai!G17+Juin!G17+Juillet!G17+Aout!G17+Septembre!G17+Octobre!G17+Novembre!G17+Décembre!G17 | H17: =Janvier!H17+Février!H17+Mars!H17+Avril!H17+Mai!H17+Juin!H17+Juillet!H17+Aout!H17+Septembre!H17+Octobre!H17+Novembre!H17+Décembre!H17 | I17: =Janvier!I17+Février!I17+Mars!I17+Avril!I17+Mai!I17+Juin!I17+Juillet!I17+Aout!I17+Septembre!I17+Octobre!I17+Novembre!I17+Décembre!I17 | J17: =Janvier!J17+Février!J17+Mars!J17+Avril!J17+Mai!J17+Juin!J17+Juillet!J17+Aout!J17+Septembre!J17+Octobre!J17+Novembre!J17+Décembre!J17 | L17: =SUM(E17:F17,I17:K17) | M17: =L17+D17 | N17: =M17/655.957 | O17: =A17 | P17: =B17 | Q17: =C17 | R17: =D17 | S17: =X17/12*$A$1 | T17: =Y17/12*$A$1 | U17: 41667000 | V17: =$R17-U17 | W17: =R17/U17-1 | X17: 335000000 | Y17: 300000000 | Z17: =Y17+X17 | AA17: =R17-Z17 | AB17: =R17/Z17-1 | AC17: =Z17/$Z$57 | AD17: =(6900000*6)+(27649000*6) | AE17: =AF17-AD17 | AF17: 600000000 | AG17: =R17-AF17 | AH17: =R17/AF17-1 | AI17: 247294000 | AJ17: =AK17-AI17 | AK17: 787294000 | AL17: =R17-AK17 | AM17: =R17/AK17-1 | AN17: =AI17/12*$A$1 | AO17: =AJ17/12*$A$1 | AP17: =AO17+AN17 | AQ17: =R17-AP17 | AR17: =R17/AP17-1 | AS17: =83748000*4 | AT17: =247000000+6*45000000+25000000+30000000 | AU17: =AT17+AS17 | AV17: =AU17-Z17 | AW17: =AU17/Z17-1 | AX17: =BC17/12*$A$1 | AY17: =BD17/12*$A$1 | AZ17: =AY17+AX17 | BA17: =$R17-AZ17 | BB17: =$R17/AZ17-1 | BC17: 335000000 | BD17: 850000000 | BE17: =BD17+BC17 | BF17: =$R17-BE17 | BG17: =$R17/BE17-1
A18: COMEXAS - CI | B18: =Janvier!B18+Février!B18+Mars!B18+Avril!B18+Mai!B18+Juin!B18+Juillet!B18+Aout!B18+Septembre!B18+Octobre!B18+Novembre!B18+Décembre!B18 | C18: =Janvier!C18+Février!C18+Mars!C18+Avril!C18+Mai!C18+Juin!C18+Juillet!C18+Aout!C18+Septembre!C18+Octobre!C18+Novembre!C18+Décembre!C18 | D18: =Janvier!D18+Février!D18+Mars!D18+Avril!D18+Mai!D18+Juin!D18+Juillet!D18+Aout!D18+Septembre!D18+Octobre!D18+Novembre!D18+Décembre!D18 | E18: =Janvier!E18+Février!E18+Mars!E18+Avril!E18+Mai!E18+Juin!E18+Juillet!E18+Aout!E18+Septembre!E18+Octobre!E18+Novembre!E18+Décembre!E18 | F18: =Janvier!F18+Février!F18+Mars!F18+Avril!F18+Mai!F18+Juin!F18+Juillet!F18+Aout!F18+Septembre!F18+Octobre!F18+Novembre!F18+Décembre!F18 | G18: =Janvier!G18+Février!G18+Mars!G18+Avril!G18+Mai!G18+Juin!G18+Juillet!G18+Aout!G18+Septembre!G18+Octobre!G18+Novembre!G18+Décembre!G18 | H18: =Janvier!H18+Février!H18+Mars!H18+Avril!H18+Mai!H18+Juin!H18+Juillet!H18+Aout!H18+Septembre!H18+Octobre!H18+Novembre!H18+Décembre!H18 | I18: =Janvier!I18+Février!I18+Mars!I18+Avril!I18+Mai!I18+Juin!I18+Juillet!I18+Aout!I18+Septembre!I18+Octobre!I18+Novembre!I18+Décembre!I18 | J18: =Janvier!J18+Février!J18+Mars!J18+Avril!J18+Mai!J18+Juin!J18+Juillet!J18+Aout!J18+Septembre!J18+Octobre!J18+Novembre!J18+Décembre!J18 | L18: =SUM(E18:F18,I18:K18) | M18: =L18+D18 | N18: =M18/655.957 | O18: =A18 | P18: =B18 | Q18: =C18 | R18: =D18 | S18: =X18/12*$A$1 | T18: =Y18/12*$A$1 | U18: 0 | V18: =$R18-U18 | W18: =R18/U18-1 | Z18: =Y18+X18 | AA18: =R18-Z18 | AB18: =R18/Z18-1 | AC18: =Z18/$Z$57 | AE18: =AF18-AD18 | AF18: =AC18*4901000000 | AG18: =R18-AF18 | AH18: =R18/AF18-1 | AJ18: =AK18-AI18 | AK18: 0 | AL18: =R18-AK18 | AM18: 0 | AN18: =AI18/12*$A$1 | AO18: =AJ18/12*$A$1 | AP18: =AO18+AN18 | AQ18: =R18-AP18 | AR18: 0 | AU18: =AT18+AS18 | AV18: =AU18-Z18 | AW18: =AU18/Z18-1 | AX18: =BC18/12*$A$1 | AY18: =BD18/12*$A$1 | AZ18: =AY18+AX18 | BA18: =$R18-AZ18 | BB18: =$R18/AZ18-1 | BE18: =BD18+BC18 | BF18: =$R18-BE18 | BG18: =$R18/BE18-1
