Workbook

Sheet PROGRAMME 2014
B2: OCT. 2012 | F2: NOV. 2012 | J2: DEC. 2012 | N2: 41640 | R2: 41671 | V2: 41699 | Z2: 41730 | AD2: 41760 | AH2: 41791 | AL2: 41821 | AP2: 41852 | AT2: 41883 | AX2: 41913 | BB2: 41944 | BF2: 41974 | BJ2: COMMENTAIRES
N3: 5 | O3: 12 | P3: 19 | Q3: 26
A4: E. Raude | BJ4: Campagne Terminée - Annonce découverte et poursuite en S1/2015 - Départ 06/2014 des équipes sur place.
A6: TEPCI
A7: West Leo | BJ7: Cas de Force majeure / Campagne en suspend suite enquête US DoJ
A9: Tullow Guinea
A10: New Rig - Espoir | BJ10: Rencontre faites avec SK-Drilling (Contact : Eoin Christie). Rig prévu arrivée en juin 2014 - Manutention démarre 08/2014 avec équipes dédiées
A12: CNR
A13: New Rig - Baobab
A15: CNR
A16: B. Dolphin
A18: Anadarko
BJ19: Annonce du retrait de l'appel d'offre - Situation du projet inconnu.
A20: E. Raude - VTO
A22: Foxtrot Rig | BJ22: Démarrage manutention prévue début S2/2014 avec équipement dédié
A24: Foxtrot
A25: E. Raude | BJ25: Campagne terminée - Pas d'annonce de découverte.
A27: Lukoil
A28: Ops Foxtrot
A30: SUBTEC
A31: Marlin Project
A33: ORTEC / FRIEDLANDER
A34: Services (seismic) | BJ34: Campagne terminée
A36: CGG
A37: West Tellus
A39: CHEVRON Liberia
A41: TRANSIT | U41: TRANSIT + CONSIGNATION | AJ41: OPS Sur Base ALCI (touchées de quai) | AX41: MANUTENTION
A44: TRANSIT + MANUT | U44: MANUTENTION + CONSIGNATION | AJ44: OPS Sur Base SEPBA Vridi | AX44: A DEFINIR
A47: TRANSIT + MANUT + CONSIGNATION

Sheet SOA Envoyés
B2: 42736 | C2: 42767 | D2: 42795 | E2: 42826 | F2: 42856 | G2: 42887 | H2: 42917 | I2: 42948 | J2: 42979 | K2: 43009 | L2: 43040 | M2: 43070
A3: Anadarko | B3: x | C3: x
A4: Baker Hugues | B4: x | C4: x
A5: CNR
A6: ExxonMobil | C6: x
A7: EXPRO GROUP NORTH SEA / S-Traitant | B7: x
A8: FOXTROT
A9: GLOBAL ENERGY
A10: HALLIBURTON | B10: x | C10: x
A11: MI
A12: NOPCI - MODEC
A13: Prosafe
A14: SCHLUMBERGER
A15: Sapura Kencana Drilling | B15: x
A16: SUBTEC
A17: TOTAL E&P COTE D'IVOIRE
A18: WEATHERFORD | B18: x | C18: x
A19: Weltec

Sheet Représentations
A2: Taux de rétrocessions (%)
A3: Département | B3: Janvier | C3: Février | D3: Mars | E3: Avril | F3: Mai | G3: Juin | H3: Juillet | I3: Août | J3: Septembre | K3: Octobre | L3: Novembre | M3: Décembre
A4: Import Maritime | B4: =Janvier!E53 | C4: 0 | D4: =Mars!E53 | E4: =Avril!E53 | F4: =Mai!E53 | G4: =Juin!E53 | H4: =Juillet!E53 | I4: =Aout!E53 | J4: =Septembre!E53 | K4: =Octobre!E53 | L4: =Novembre!E53 | M4: =Décembre!E53
A5: Hinterland | B5: =Janvier!F53 | C5: =Février!F53 | D5: =Mars!F53 | E5: =Avril!F53 | F5: =Mai!F53 | G5: =Juin!F53 | H5: =Juillet!F53 | I5: =Aout!F53 | J5: =Septembre!F53 | K5: =Octobre!F53 | L5: =Novembre!F53 | M5: =Décembre!F53
A6: Aérien | B6: =Janvier!I53 | C6: =Février!I53 | D6: =Mars!I53 | E6: =Avril!I53 | F6: =Mai!I53 | G6: =Juin!I53 | H6: =Juillet!I53 | I6: =Aout!I53 | J6: =Septembre!I53 | K6: =Octobre!I53 | L6: =Novembre!I53 | M6: =Décembre!I53
A7: Export Maritime | B7: =Janvier!J53 | C7: =Février!J53 | D7: =Mars!J53 | E7: =Avril!J53 | F7: =Mai!J53 | G7: =Juin!J53 | H7: =Juillet!J53 | I7: =Aout!J53 | J7: =Septembre!J53 | K7: =Octobre!J53 | L7: =Novembre!J53 | M7: =Décembre!J53
A8: SIRT (dédié) | B8: =Janvier!#REF! | C8: =Février!N53 | D8: =Mars!K53 | E8: =Avril!K53 | F8: =Mai!K53 | G8: =Juin!K53 | H8: =Juillet!K53 | I8: =Aout!K53 | J8: =Septembre!K53 | K8: =Octobre!K53 | L8: =Novembre!K53 | M8: =Décembre!K53
A27: Volume de rétrocessions (FCFA)
A28: Département | B28: Janvier | C28: Février | D28: Mars | E28: Avril | F28: Mai | G28: Juin | H28: Juillet | I28: Août | J28: Septembre | K28: Octobre | L28: Novembre | M28: Décembre
A29: Import Maritime | B29: =Janvier!E52 | C29: =Février!E52 | D29: =Mars!E52 | E29: =Avril!E52 | F29: =Mai!E52 | G29: =Juin!E52 | H29: =Juillet!E52 | I29: =Aout!E52 | J29: =Septembre!E52 | K29: =Octobre!E52 | L29: =Novembre!E52 | M29: =Décembre!E52
A30: Hinterland | B30: =Janvier!F52 | C30: =Février!F52 | D30: =Mars!F52 | E30: =Avril!F52 | F30: =Mai!F52 | G30: =Juin!F52 | H30: =Juillet!F52 | I30: =Aout!F52 | J30: =Septembre!F52 | K30: =Octobre!F52 | L30: =Novembre!F52 | M30: =Décembre!F52
A31: Aérien | B31: =Janvier!I52 | C31: =Février!I52 | D31: =Mars!I52 | E31: =Avril!I52 | F31: =Mai!I52 | G31: =Juin!I52 | H31: =Juillet!I52 | I31: =Aout!I52 | J31: =Septembre!I52 | K31: =Octobre!I52 | L31: =Novembre!I52 | M31: =Décembre!I52
A32: Export Maritime | B32: =Janvier!J52 | C32: =Février!J52 | D32: =Mars!J52 | E32: =Avril!J52 | F32: =Mai!J52 | G32: =Juin!J52 | H32: =Juillet!J52 | I32: =Aout!J52 | J32: =Septembre!J52 | K32: =Octobre!J52 | L32: =Novembre!J52 | M32: =Décembre!J52
A33: SIRT (dédié) | B33: =Janvier!#REF! | C33: =Février!N52 | D33: =Mars!K52 | E33: =Avril!K52 | F33: =Mai!K52 | G33: =Juin!K52 | H33: =Juillet!K52 | I33: =Aout!K52 | J33: =Septembre!K52 | K33: =Octobre!K52 | L33: =Novembre!K52 | M33: =Décembre!K52
A54: Volume de CA généré par les Dpt sur l'activité O&G (FCFA)
A55: Département | B55: Janvier | C55: Février | D55: Mars | E55: Avril | F55: Mai | G55: Juin | H55: Juillet | I55: Août | J55: Septembre | K55: Octobre | L55: Novembre | M55: Décembre
A56: Import Maritime | B56: =Janvier!E51 | C56: =Février!E51 | D56: =Mars!E51 | E56: =Avril!E51 | F56: =Mai!E51 | G56: =Juin!E51 | H56: =Juillet!E51 | I56: =Aout!E51 | J56: =Septembre!E51 | K56: =Octobre!E51 | L56: =Novembre!E51 | M56: =Décembre!E51
A57: Hinterland | B57: =Janvier!F51 | C57: =Février!F51 | D57: =Mars!F51 | E57: =Avril!F51 | F57: =Mai!F51 | G57: =Juin!F51 | H57: =Juillet!F51 | I57: =Aout!F51 | J57: =Septembre!F51 | K57: =Octobre!F51 | L57: =Novembre!F51 | M57: =Décembre!F51
A58: Aérien | B58: =Janvier!I51 | C58: =Février!I51 | D58: =Mars!I51 | E58: =Avril!I51 | F58: =Mai!I51 | G58: =Juin!I51 | H58: =Juillet!I51 | I58: =Aout!I51 | J58: =Septembre!I51 | K58: =Octobre!I51 | L58: =Novembre!I51 | M58: =Décembre!I51
A59: Export Maritime | B59: =Janvier!J51 | C59: =Février!J51 | D59: =Mars!J51 | E59: =Avril!J51 | F59: =Mai!J51 | G59: =Juin!J51 | H59: =Juillet!J51 | I59: =Aout!J51 | J59: =Septembre!J51 | K59: =Octobre!J51 | L59: =Novembre!J51 | M59: =Décembre!J51
A60: CA BASE | B60: 333829612 | C60: 205124188 | D60: 292894213 | E60: 319413776 | F60: 225715537 | G60: 207075389 | H60: 295412277 | I60: 224962510 | J60: 281259944 | K60: 292800598 | L60: 527147802 | M60: 398175063
A81: Evolution CA Base O&G (FCFA)
A82: Section | B82: Janvier | C82: Février | D82: Mars | E82: Avril | F82: Mai | G82: Juin | H82: Juillet | I82: Août | J82: Septembre | K82: Octobre | L82: Novembre | M82: Décembre
A83: Loyers | B83: =Janvier!B51 | C83: =Février!B51 | D83: =Mars!B51 | E83: =Avril!B51 | F83: =Mai!B51 | G83: =Juin!B51 | H83: =Juillet!B51 | I83: =Aout!B51 | J83: =Septembre!B51 | K83: =Octobre!B51 | L83: =Novembre!B51 | M83: =Décembre!B51
A84: Log & Divers | B84: =Janvier!C51 | C84: =Février!C51 | D84: =Mars!C51 | E84: =Avril!C51 | F84: =Mai!C51 | G84: =Juin!C51 | H84: =Juillet!C51 | I84: =Aout!C51 | J84: =Septembre!C51 | K84: =Octobre!C51 | L84: =Novembre!C51 | M84: =Décembre!C51
A85: Rétrocession | B85: =Janvier!N52 | C85: =Février!O52 | D85: =Mars!L52 | E85: =Avril!L52 | F85: =Mai!L52 | G85: =Juin!L52 | H85: =Juillet!L52 | I85: =Aout!L52 | J85: =Septembre!L52 | K85: =Octobre!L52 | L85: =Novembre!L52 | M85: =Décembre!L52
A86: CA BASE | B86: =SUBTOTAL(109,B83:B85) | C86: =SUBTOTAL(109,C83:C85) | D86: =SUBTOTAL(109,D83:D85) | E86: =SUBTOTAL(109,E83:E85) | F86: =SUBTOTAL(109,F83:F85) | G86: =SUBTOTAL(109,G83:G85) | H86: =SUBTOTAL(109,H83:H85) | I86: =SUBTOTAL(109,I83:I85) | ... M86: =SUBTOTAL(109,M83:M85)

Sheet Evolution clients
A4: Anadarko | B4: Logistique | C4: IMAR | D4: HINT | E4: IAER | F4: EAER | G4: AERIEN | H4: EXPORT | I4: SIRT | J4: Afritramp | K4: Meet & Greet | L4: Total mensuel | M4: Total mensuel | N4: Cumul
A5: Janvier | B5: =Janvier!D$6 | C5: =Janvier!E$6 | D5: =Janvier!F$6 | E5: =Janvier!G$6 | F5: =Janvier!H$6 | G5: =Janvier!I$6 | H5: =Janvier!J$6 | I5: =Janvier!K$6 | ... K5: =Janvier!M$6 | L5: =B5+C5+D5+E5+F5+H5+J5+K5 | M5: =L5/655.957 | N5: =M5
A6: Février | B6: =Février!D6 | C6: =Février!E6 | D6: =Février!F6 | E6: =Février!G6 | F6: =Février!H6 | G6: =Février!I6 | H6: =Février!J6 | I6: =Février!K6 | ... K6: =Février!M6 | L6: =B6+C6+D6+E6+F6+H6+J6+K6 | M6: =L6/655.957 | N6: =N5+M6
A7: Mars | B7: =Mars!D6 | C7: =Mars!E6 | D7: =Mars!F6 | E7: =Mars!G6 | F7: =Mars!H6 | G7: =Mars!I6 | H7: =Mars!J6 | I7: =Mars!K6 | ... K7: =Mars!M6 | L7: =B7+C7+D7+E7+F7+H7+J7+K7 | M7: =L7/655.957 | N7: =N6+M7
A8: Avril | B8: =Avril!D6 | C8: =Avril!E6 | D8: =Avril!F6 | E8: =Avril!G6 | F8: =Avril!H6 | G8: =Avril!I6 | H8: =Avril!J6 | I8: =Avril!K6 | ... K8: =Avril!M6 | L8: =B8+C8+D8+E8+F8+H8+J8+K8 | M8: =L8/655.957 | N8: =N7+M8
A9: Mai | B9: =Mai!D6 | C9: =Mai!E6 | D9: =Mai!F6 | E9: =Mai!G6 | F9: =Mai!H6 | G9: =Mai!I6 | H9: =Mai!J6 | I9: =Mai!K6 | ... K9: =Mai!M6 | L9: =B9+C9+D9+E9+F9+H9+J9+K9 | M9: =L9/655.957 | N9: =N8+M9
A10: Juin | B10: =Juin!D6 | C10: =Juin!E6 | D10: =Juin!F6 | E10: =Juin!G6 | F10: =Juin!H6 | G10: =Juin!I6 | H10: =Juin!J6 | I10: =Juin!K6 | ... K10: =Juin!M6 | L10: =B10+C10+D10+E10+F10+H10+J10+K10 | M10: =L10/655.957 | N10: =N9+M10
A11: Juillet | B11: =Juillet!D6 | C11: =Juillet!E6 | D11: =Juillet!F6 | E11: =Juillet!G6 | F11: =Juillet!H6 | G11: =Juillet!I6 | H11: =Juillet!J6 | I11: =Juillet!K6 | ... K11: =Juillet!M6 | L11: =B11+C11+D11+E11+F11+H11+J11+K11 | M11: =L11/655.957 | N11: =N10+M11
A12: Août | B12: =Aout!D6 | C12: =Aout!E6 | D12: =Aout!F6 | E12: =Aout!G6 | F12: =Aout!H6 | G12: =Aout!I6 | H12: =Aout!J6 | I12: =Aout!K6 | ... K12: =Aout!M6 | L12: =B12+C12+D12+E12+F12+H12+J12+K12 | M12: =L12/655.957 | N12: =N11+M12
A13: Septembre | B13: =Septembre!D6 | C13: =Septembre!E6 | D13: =Septembre!F6 | E13: =Septembre!G6 | F13: =Septembre!H6 | G13: =Septembre!I6 | H13: =Septembre!J6 | I13: =Septembre!K6 | ... K13: =Septembre!M6 | L13: =B13+C13+D13+E13+F13+H13+J13+K13 | M13: =L13/655.957 | N13: =N12+M13
A14: Octobre | B14: =Octobre!D6 | C14: =Octobre!E6 | D14: =Octobre!F6 | E14: =Octobre!G6 | F14: =Octobre!H6 | G14: =Octobre!I6 | H14: =Octobre!J6 | I14: =Octobre!K6 | ... K14: =Octobre!M6 | L14: =B14+C14+D14+E14+F14+H14+J14+K14 | M14: =L14/655.957 | N14: =N13+M14
A15: Novembre | B15: =Novembre!D6 | C15: =Novembre!E6 | D15: =Novembre!F6 | E15: =Novembre!G6 | F15: =Novembre!H6 | G15: =Novembre!I6 | H15: =Novembre!J6 | I15: =Novembre!K6 | ... K15: =Novembre!M6 | L15: =B15+C15+D15+E15+F15+H15+J15+K15 | M15: =L15/655.957 | N15: =N14+M15
A16: Décembre | B16: =Décembre!D6 | C16: =Décembre!E6 | D16: =Décembre!F6 | E16: =Décembre!G6 | F16: =Décembre!H6 | G16: =Décembre!I6 | H16: =Décembre!J6 | I16: =Décembre!K6 | ... K16: =Décembre!M6 | L16: =B16+C16+D16+E16+F16+H16+J16+K16 | M16: =L16/655.957 | N16: =N15+M16
A17: Total Annuel (FCFA) | B17: =SUM(B5:B16) | C17: =SUM(C5:C16) | D17: =SUM(D5:D16) | E17: =SUM(E5:E16) | F17: =SUM(F5:F16) | G17: =SUM(G5:G16) | H17: =SUM(H5:H16) | I17: =SUM(I5:I16) | ... L17: =SUM(L5:L16)
A18: Total (€) | B18: =B17/655.957 | C18: =C17/655.957 | D18: =D17/655.957 | E18: =E17/655.957 | F18: =F17/655.957 | G18: =G17/655.957 | H18: =H17/655.957 | I18: =I17/655.957 | ... K18: =K17/655.957 | M18: =L17/655.957
A21: Baker Hughes | B21: Logistique | C21: IMAR | D21: HINT | E21: IAER | F21: EAER | G21: AERIEN | H21: EXPORT | I21: SIRT | J21: Afritramp | K21: Meet & Greet | L21: Total mensuel | M21: Total mensuel
A22: Janvier | B22: =Janvier!D7 | C22: =Janvier!E7 | D22: =Janvier!F7 | E22: =Janvier!G7 | F22: =Janvier!H7 | G22: =Janvier!I7 | H22: =Janvier!J7 | I22: =Janvier!K7 | ... K22: =Janvier!M7 | L22: =B22+C22+D22+E22+F22+H22+J22+K22 | M22: =L22/655.957
A23: Février | B23: =Février!D7 | C23: =Février!E7 | D23: =Février!F7 | E23: =Février!G7 | F23: =Février!H7 | G23: =Février!I7 | H23: =Février!J7 | I23: =Février!K7 | ... K23: =Février!M7 | L23: =B23+C23+D23+E23+F23+H23+J23+K23 | M23: =L23/655.957
A24: Mars | B24: =Mars!D7 | C24: =Mars!E7 | D24: =Mars!F7 | E24: =Mars!G7 | F24: =Mars!H7 | G24: =Mars!I7 | H24: =Mars!J7 | I24: =Mars!K7 | ... K24: =Mars!M7 | L24: =B24+C24+D24+E24+F24+H24+J24+K24 | M24: =L24/655.957
A25: Avril | B25: =Avril!D7 | C25: =Avril!E7 | D25: =Avril!F7 | E25: =Avril!G7 | F25: =Avril!H7 | G25: =Avril!I7 | H25: =Avril!J7 | I25: =Avril!K7 | ... K25: =Avril!M7 | L25: =B25+C25+D25+E25+F25+H25+J25+K25 | M25: =L25/655.957
A26: Mai | B26: =Mai!D7 | C26: =Mai!E7 | D26: =Mai!F7 | E26: =Mai!G7 | F26: =Mai!H7 | G26: =Mai!I7 | H26: =Mai!J7 | I26: =Mai!K7 | ... K26: =Mai!M7 | L26: =B26+C26+D26+E26+F26+H26+J26+K26 | M26: =L26/655.957
A27: Juin | B27: =Juin!D7 | C27: =Juin!E7 | D27: =Juin!F7 | E27: =Juin!G7 | F27: =Juin!H7 | G27: =Juin!I7 | H27: =Juin!J7 | I27: =Juin!K7 | ... K27: =Juin!M7 | L27: =B27+C27+D27+E27+F27+H27+J27+K27 | M27: =L27/655.957
A28: Juillet | B28: =Juillet!D7 | C28: =Juillet!E7 | D28: =Juillet!F7 | E28: =Juillet!G7 | F28: =Juillet!H7 | G28: =Juillet!I7 | H28: =Juillet!J7 | I28: =Juillet!K7 | ... K28: =Juillet!M7 | L28: =B28+C28+D28+E28+F28+H28+J28+K28 | M28: =L28/655.957
A29: Août | B29: =Aout!D7 | C29: =Aout!E7 | D29: =Aout!F7 | E29: =Aout!G7 | F29: =Aout!H7 | G29: =Aout!I7 | H29: =Aout!J7 | I29: =Aout!K7 | ... K29: =Aout!M7 | L29: =B29+C29+D29+E29+F29+H29+J29+K29 | M29: =L29/655.957
A30: Septembre | B30: =Septembre!D7 | C30: =Septembre!E7 | D30: =Septembre!F7 | E30: =Septembre!G7 | F30: =Septembre!H7 | G30: =Septembre!I7 | H30: =Septembre!J7 | I30: =Septembre!K7 | ... K30: =Septembre!M7 | L30: =B30+C30+D30+E30+F30+H30+J30+K30 | M30: =L30/655.957
A31: Octobre | B31: =Octobre!D7 | C31: =Octobre!E7 | D31: =Octobre!F7 | E31: =Octobre!G7 | F31: =Octobre!H7 | G31: =Octobre!I7 | H31: =Octobre!J7 | I31: =Octobre!K7 | ... K31: =Octobre!M7 | L31: =B31+C31+D31+E31+F31+H31+J31+K31 | M31: =L31/655.957
A32: Novembre | B32: =Novembre!D7 | C32: =Novembre!E7 | D32: =Novembre!F7 | E32: =Novembre!G7 | F32: =Novembre!H7 | G32: =Novembre!I7 | H32: =Novembre!J7 | I32: =Novembre!K7 | ... K32: =Novembre!M7 | L32: =B32+C32+D32+E32+F32+H32+J32+K32 | M32: =L32/655.957
A33: Décembre | B33: =Décembre!D7 | C33: =Décembre!E7 | D33: =Décembre!F7 | E33: =Décembre!G7 | F33: =Décembre!H7 | G33: =Décembre!I7 | H33: =Décembre!J7 | I33: =Décembre!K7 | ... K33: =Décembre!M7 | L33: =B33+C33+D33+E33+F33+H33+J33+K33 | M33: =L33/655.957
A34: Total Annuel (FCFA) | B34: =SUM(B22:B33) | C34: =SUM(C22:C33) | D34: =SUM(D22:D33) | E34: =SUM(E22:E33) | F34: =SUM(F22:F33) | G34: =SUM(G22:G33) | H34: =SUM(H22:H33) | I34: =SUM(I22:I33) | ... L34: =SUM(L22:L33)
A35: Total (€) | B35: =B34/655.957 | C35: =C34/655.957 | D35: =D34/655.957 | E35: =E34/655.957 | F35: =F34/655.957 | G35: =G34/655.957 | H35: =H34/655.957 | I35: =I34/655.957 | ... K35: =K34/655.957 | M35: =L34/655.957
A38: CNR International | B38: Logistique | C38: IMAR | D38: HINT | E38: IAER | F38: EAER | G38: AERIEN | H38: EXPORT | I38: SIRT | J38: Afritramp | K38: Meet & Greet | L38: Total mensuel | M38: Total mensuel
A39: Janvier | B39: =Janvier!D11 | C39: =Janvier!E11 | D39: =Janvier!F11 | E39: =Janvier!G11 | F39: =Janvier!H11 | G39: =Janvier!I11 | H39: =Janvier!J11 | I39: =Janvier!K11 | ... K39: =Janvier!M11 | L39: =B39+C39+D39+E39+F39+H39+J39+K39 | M39: =L39/655.957
A40: Février | B40: =Février!D11 | C40: =Février!E11 | D40: =Février!F11 | E40: =Février!G11 | F40: =Février!H11 | G40: =Février!I11 | H40: =Février!J11 | I40: =Février!K11 | ... K40: =Février!M11 | L40: =B40+C40+D40+E40+F40+H40+J40+K40 | M40: =L40/655.957
A41: Mars | B41: =Mars!D11 | C41: =Mars!E11 | D41: =Mars!F11 | E41: =Mars!G11 | F41: =Mars!H11 | G41: =Mars!I11 | H41: =Mars!J11 | I41: =Mars!K11 | ... K41: =Mars!M11 | L41: =B41+C41+D41+E41+F41+H41+J41+K41 | M41: =L41/655.957
A42: Avril | B42: =Avril!D11 | C42: =Avril!E11 | D42: =Avril!F11 | E42: =Avril!G11 | F42: =Avril!H11 | G42: =Avril!I11 | H42: =Avril!J11 | I42: =Avril!K11 | ... K42: =Avril!M11 | L42: =B42+C42+D42+E42+F42+H42+J42+K42 | M42: =L42/655.957
A43: Mai | B43: =Mai!D11 | C43: =Mai!E11 | D43: =Mai!F11 | E43: =Mai!G11 | F43: =Mai!H11 | G43: =Mai!I11 | H43: =Mai!J11 | I43: =Mai!K11 | ... K43: =Mai!M11 | L43: =B43+C43+D43+E43+F43+H43+J43+K43 | M43: =L43/655.957
A44: Juin | B44: =Juin!D11 | C44: =Juin!E11 | D44: =Juin!F11 | E44: =Juin!G11 | F44: =Juin!H11 | G44: =Juin!I11 | H44: =Juin!J11 | I44: =Juin!K11 | ... K44: =Juin!M11 | L44: =B44+C44+D44+E44+F44+H44+J44+K44 | M44: =L44/655.957
A45: Juillet | B45: =Juillet!D11 | C45: =Juillet!E11 | D45: =Juillet!F11 | E45: =Juillet!G11 | F45: =Juillet!H11 | G45: =Juillet!I40 | H45: =Juillet!J11 | I45: =Juillet!K40 | J45: =Juillet!L11 | K45: =Juillet!M11 | L45: =B45+C45+D45+E45+F45+H45+J45+K45 | M45: =L45/655.957
A46: Août | B46: =Aout!D11 | C46: =Aout!E11 | D46: =Aout!F11 | E46: =Aout!G11 | F46: =Aout!H11 | G46: =Aout!I11 | H46: =Aout!J11 | I46: =Aout!K11 | ... K46: =Aout!M11 | L46: =B46+C46+D46+E46+F46+H46+J46+K46 | M46: =L46/655.957
A47: Septembre | B47: =Septembre!D11 | C47: =Septembre!E11 | D47: =Septembre!F11 | E47: =Septembre!G11 | F47: =Septembre!H11 | G47: =Septembre!I11 | H47: =Septembre!J11 | I47: =Septembre!K11 | ... K47: =Septembre!M11 | L47: =B47+C47+D47+E47+F47+H47+J47+K47 | M47: =L47/655.957
...
